Workbook

Sheet Instructions
A1: Country scoring model: Julius Meinl, Latin America
A2: Business Projects WT 2026/27, Midterm Part A. One workbook for all six groups.
A4: Purpose | B4: All groups score the same six countries with the same criteria and the same weights. Each group collects the data of its allocated country. The workbook turns the data into scores and ranks.
A5: Your country | B5: Group 1: Argentina. Group 2: Chile. Group 3: Mexico. Group 4: Colombia. Group 5: Uruguay. Group 6: Brazil.
A6: What you enter | B6: Only on the Data sheet, only in the yellow cells of your own country: value, year and source (name and link). Do not type in other groups' columns. Never type over a grey or white cell: they contain formulas.
A7: How the criteria are built | B7: The 14 indicators are grouped by the six PESTEL dimensions (Political, Economic, Social, Technological, Environmental, Legal). Julius Meinl's six dimensions are shown as a second label.
A8: How the weights work | B8: The instructor has fixed the weight of each PESTEL dimension upfront (sheet Weights). The weight of a dimension is split equally among its indicators. Groups cannot change the weights.
A9: How scores are calculated | B9: Each indicator is rescaled to 0 to 100 across the six countries (min-max, direction respected). The score of a country is the weighted sum of its indicator scores. The T-scores sheet shows a second normalisation (50 + 10 x z-score; 50 = average of the six countries).
A10: Robustness | B10: The Scores sheet recalculates the ranking with four alternative weight sets. Use it for Step 7 of the student brief.
A11: Colour code | B11: Yellow with blue text: input. Grey: fixed by the instructor. White or light grey with black text: formula.
A12: Quality rules | B12: Use the latest year available. Use the unit given. Record the year and a source link for every value. Qualitative scores use the rubrics on the Rubrics sheet; write the reason in the source cell. A country with a missing value shows "incomplete" instead of a score.
A13: Questions | B13: arne.floh@wu.ac.at

Sheet Weights
A1: Weights (set by the instructor, do not change)
A3: PESTEL dimension | B3: Baseline | C3: Equal | D3: Economy-led | E3: Access-led | F3: Society-led | G3: Indicators in dimension
A4: Political | B4: 15 | C4: 17 | D4: 10 | E4: 20 | F4: 10 | G4: =COUNTIF(Indicators!$B$4:$B$17,A4)
A5: Economic | B5: 25 | C5: 17 | D5: 40 | E5: 15 | F5: 20 | G5: =COUNTIF(Indicators!$B$4:$B$17,A5)
A6: Social | B6: 25 | C6: 17 | D6: 20 | E6: 15 | F6: 40 | G6: =COUNTIF(Indicators!$B$4:$B$17,A6)
A7: Technological | B7: 10 | C7: 17 | D7: 10 | E7: 5 | F7: 10 | G7: =COUNTIF(Indicators!$B$4:$B$17,A7)
A8: Environmental | B8: 5 | C8: 16 | D8: 5 | E8: 5 | F8: 5 | G8: =COUNTIF(Indicators!$B$4:$B$17,A8)
A9: Legal | B9: 20 | C9: 16 | D9: 15 | E9: 40 | F9: 15 | G9: =COUNTIF(Indicators!$B$4:$B$17,A9)
A10: Sum (must be 100) | B10: =SUM(B4:B9) | C10: =SUM(C4:C9) | D10: =SUM(D4:D9) | E10: =SUM(E4:E9) | F10: =SUM(F4:F9) | G10: =SUM(G4:G9)
A12: Baseline: derived from Julius Meinl's priorities (purchasing power and coffee culture first, import conditions and regulation next). Economy-led, Access-led and Society-led shift the emphasis. Equal is the neutral benchmark.
A15: Weight of each indicator (dimension weight divided by the number of indicators in the dimension)
A16: ID | B16: Indicator (dimension) | C16: Baseline | D16: Equal | E16: Economy-led | F16: Access-led | G16: Society-led
A17: =Indicators!A4 | B17: =Indicators!C4&" ("&Indicators!B4&")" | C17: =INDEX($B$4:$B$9,MATCH(Indicators!$B4,$A$4:$A$9,0))/INDEX($G$4:$G$9,MATCH(Indicators!$B4,$A$4:$A$9,0)) | D17: =INDEX($C$4:$C$9,MATCH(Indicators!$B4,$A$4:$A$9,0))/INDEX($G$4:$G$9,MATCH(Indicators!$B4,$A$4:$A$9,0)) | E17: =INDEX($D$4:$D$9,MATCH(Indicators!$B4,$A$4:$A$9,0))/INDEX($G$4:$G$9,MATCH(Indicators!$B4,$A$4:$A$9,0)) | F17: =INDEX($E$4:$E$9,MATCH(Indicators!$B4,$A$4:$A$9,0))/INDEX($G$4:$G$9,MATCH(Indicators!$B4,$A$4:$A$9,0)) | G17: =INDEX($F$4:$F$9,MATCH(Indicators!$B4,$A$4:$A$9,0))/INDEX($G$4:$G$9,MATCH(Indicators!$B4,$A$4:$A$9,0))
A18: =Indicators!A5 | B18: =Indicators!C5&" ("&Indicators!B5&")" | C18: =INDEX($B$4:$B$9,MATCH(Indicators!$B5,$A$4:$A$9,0))/INDEX($G$4:$G$9,MATCH(Indicators!$B5,$A$4:$A$9,0)) | D18: =INDEX($C$4:$C$9,MATCH(Indicators!$B5,$A$4:$A$9,0))/INDEX($G$4:$G$9,MATCH(Indicators!$B5,$A$4:$A$9,0)) | E18: =INDEX($D$4:$D$9,MATCH(Indicators!$B5,$A$4:$A$9,0))/INDEX($G$4:$G$9,MATCH(Indicators!$B5,$A$4:$A$9,0)) | F18: =INDEX($E$4:$E$9,MATCH(Indicators!$B5,$A$4:$A$9,0))/INDEX($G$4:$G$9,MATCH(Indicators!$B5,$A$4:$A$9,0)) | G18: =INDEX($F$4:$F$9,MATCH(Indicators!$B5,$A$4:$A$9,0))/INDEX($G$4:$G$9,MATCH(Indicators!$B5,$A$4:$A$9,0))
A19: =Indicators!A6 | B19: =Indicators!C6&" ("&Indicators!B6&")" | C19: =INDEX($B$4:$B$9,MATCH(Indicators!$B6,$A$4:$A$9,0))/INDEX($G$4:$G$9,MATCH(Indicators!$B6,$A$4:$A$9,0)) | D19: =INDEX($C$4:$C$9,MATCH(Indicators!$B6,$A$4:$A$9,0))/INDEX($G$4:$G$9,MATCH(Indicators!$B6,$A$4:$A$9,0)) | E19: =INDEX($D$4:$D$9,MATCH(Indicators!$B6,$A$4:$A$9,0))/INDEX($G$4:$G$9,MATCH(Indicators!$B6,$A$4:$A$9,0)) | F19: =INDEX($E$4:$E$9,MATCH(Indicators!$B6,$A$4:$A$9,0))/INDEX($G$4:$G$9,MATCH(Indicators!$B6,$A$4:$A$9,0)) | G19: =INDEX($F$4:$F$9,MATCH(Indicators!$B6,$A$4:$A$9,0))/INDEX($G$4:$G$9,MATCH(Indicators!$B6,$A$4:$A$9,0))
A20: =Indicators!A7 | B20: =Indicators!C7&" ("&Indicators!B7&")" | C20: =INDEX($B$4:$B$9,MATCH(Indicators!$B7,$A$4:$A$9,0))/INDEX($G$4:$G$9,MATCH(Indicators!$B7,$A$4:$A$9,0)) | D20: =INDEX($C$4:$C$9,MATCH(Indicators!$B7,$A$4:$A$9,0))/INDEX($G$4:$G$9,MATCH(Indicators!$B7,$A$4:$A$9,0)) | E20: =INDEX($D$4:$D$9,MATCH(Indicators!$B7,$A$4:$A$9,0))/INDEX($G$4:$G$9,MATCH(Indicators!$B7,$A$4:$A$9,0)) | F20: =INDEX($E$4:$E$9,MATCH(Indicators!$B7,$A$4:$A$9,0))/INDEX($G$4:$G$9,MATCH(Indicators!$B7,$A$4:$A$9,0)) | G20: =INDEX($F$4:$F$9,MATCH(Indicators!$B7,$A$4:$A$9,0))/INDEX($G$4:$G$9,MATCH(Indicators!$B7,$A$4:$A$9,0))
A21: =Indicators!A8 | B21: =Indicators!C8&" ("&Indicators!B8&")" | C21: =INDEX($B$4:$B$9,MATCH(Indicators!$B8,$A$4:$A$9,0))/INDEX($G$4:$G$9,MATCH(Indicators!$B8,$A$4:$A$9,0)) | D21: =INDEX($C$4:$C$9,MATCH(Indicators!$B8,$A$4:$A$9,0))/INDEX($G$4:$G$9,MATCH(Indicators!$B8,$A$4:$A$9,0)) | E21: =INDEX($D$4:$D$9,MATCH(Indicators!$B8,$A$4:$A$9,0))/INDEX($G$4:$G$9,MATCH(Indicators!$B8,$A$4:$A$9,0)) | F21: =INDEX($E$4:$E$9,MATCH(Indicators!$B8,$A$4:$A$9,0))/INDEX($G$4:$G$9,MATCH(Indicators!$B8,$A$4:$A$9,0)) | G21: =INDEX($F$4:$F$9,MATCH(Indicators!$B8,$A$4:$A$9,0))/INDEX($G$4:$G$9,MATCH(Indicators!$B8,$A$4:$A$9,0))
A22: =Indicators!A9 | B22: =Indicators!C9&" ("&Indicators!B9&")" | C22: =INDEX($B$4:$B$9,MATCH(Indicators!$B9,$A$4:$A$9,0))/INDEX($G$4:$G$9,MATCH(Indicators!$B9,$A$4:$A$9,0)) | D22: =INDEX($C$4:$C$9,MATCH(Indicators!$B9,$A$4:$A$9,0))/INDEX($G$4:$G$9,MATCH(Indicators!$B9,$A$4:$A$9,0)) | E22: =INDEX($D$4:$D$9,MATCH(Indicators!$B9,$A$4:$A$9,0))/INDEX($G$4:$G$9,MATCH(Indicators!$B9,$A$4:$A$9,0)) | F22: =INDEX($E$4:$E$9,MATCH(Indicators!$B9,$A$4:$A$9,0))/INDEX($G$4:$G$9,MATCH(Indicators!$B9,$A$4:$A$9,0)) | G22: =INDEX($F$4:$F$9,MATCH(Indicators!$B9,$A$4:$A$9,0))/INDEX($G$4:$G$9,MATCH(Indicators!$B9,$A$4:$A$9,0))
A23: =Indicators!A10 | B23: =Indicators!C10&" ("&Indicators!B10&")" | C23: =INDEX($B$4:$B$9,MATCH(Indicators!$B10,$A$4:$A$9,0))/INDEX($G$4:$G$9,MATCH(Indicators!$B10,$A$4:$A$9,0)) | D23: =INDEX($C$4:$C$9,MATCH(Indicators!$B10,$A$4:$A$9,0))/INDEX($G$4:$G$9,MATCH(Indicators!$B10,$A$4:$A$9,0)) | E23: =INDEX($D$4:$D$9,MATCH(Indicators!$B10,$A$4:$A$9,0))/INDEX($G$4:$G$9,MATCH(Indicators!$B10,$A$4:$A$9,0)) | F23: =INDEX($E$4:$E$9,MATCH(Indicators!$B10,$A$4:$A$9,0))/INDEX($G$4:$G$9,MATCH(Indicators!$B10,$A$4:$A$9,0)) | G23: =INDEX($F$4:$F$9,MATCH(Indicators!$B10,$A$4:$A$9,0))/INDEX($G$4:$G$9,MATCH(Indicators!$B10,$A$4:$A$9,0))
A24: =Indicators!A11 | B24: =Indicators!C11&" ("&Indicators!B11&")" | C24: =INDEX($B$4:$B$9,MATCH(Indicators!$B11,$A$4:$A$9,0))/INDEX($G$4:$G$9,MATCH(Indicators!$B11,$A$4:$A$9,0)) | D24: =INDEX($C$4:$C$9,MATCH(Indicators!$B11,$A$4:$A$9,0))/INDEX($G$4:$G$9,MATCH(Indicators!$B11,$A$4:$A$9,0)) | E24: =INDEX($D$4:$D$9,MATCH(Indicators!$B11,$A$4:$A$9,0))/INDEX($G$4:$G$9,MATCH(Indicators!$B11,$A$4:$A$9,0)) | F24: =INDEX($E$4:$E$9,MATCH(Indicators!$B11,$A$4:$A$9,0))/INDEX($G$4:$G$9,MATCH(Indicators!$B11,$A$4:$A$9,0)) | G24: =INDEX($F$4:$F$9,MATCH(Indicators!$B11,$A$4:$A$9,0))/INDEX($G$4:$G$9,MATCH(Indicators!$B11,$A$4:$A$9,0))
A25: =Indicators!A12 | B25: =Indicators!C12&" ("&Indicators!B12&")" | C25: =INDEX($B$4:$B$9,MATCH(Indicators!$B12,$A$4:$A$9,0))/INDEX($G$4:$G$9,MATCH(Indicators!$B12,$A$4:$A$9,0)) | D25: =INDEX($C$4:$C$9,MATCH(Indicators!$B12,$A$4:$A$9,0))/INDEX($G$4:$G$9,MATCH(Indicators!$B12,$A$4:$A$9,0)) | E25: =INDEX($D$4:$D$9,MATCH(Indicators!$B12,$A$4:$A$9,0))/INDEX($G$4:$G$9,MATCH(Indicators!$B12,$A$4:$A$9,0)) | F25: =INDEX($E$4:$E$9,MATCH(Indicators!$B12,$A$4:$A$9,0))/INDEX($G$4:$G$9,MATCH(Indicators!$B12,$A$4:$A$9,0)) | G25: =INDEX($F$4:$F$9,MATCH(Indicators!$B12,$A$4:$A$9,0))/INDEX($G$4:$G$9,MATCH(Indicators!$B12,$A$4:$A$9,0))
A26: =Indicators!A13 | B26: =Indicators!C13&" ("&Indicators!B13&")" | C26: =INDEX($B$4:$B$9,MATCH(Indicators!$B13,$A$4:$A$9,0))/INDEX($G$4:$G$9,MATCH(Indicators!$B13,$A$4:$A$9,0)) | D26: =INDEX($C$4:$C$9,MATCH(Indicators!$B13,$A$4:$A$9,0))/INDEX($G$4:$G$9,MATCH(Indicators!$B13,$A$4:$A$9,0)) | E26: =INDEX($D$4:$D$9,MATCH(Indicators!$B13,$A$4:$A$9,0))/INDEX($G$4:$G$9,MATCH(Indicators!$B13,$A$4:$A$9,0)) | F26: =INDEX($E$4:$E$9,MATCH(Indicators!$B13,$A$4:$A$9,0))/INDEX($G$4:$G$9,MATCH(Indicators!$B13,$A$4:$A$9,0)) | G26: =INDEX($F$4:$F$9,MATCH(Indicators!$B13,$A$4:$A$9,0))/INDEX($G$4:$G$9,MATCH(Indicators!$B13,$A$4:$A$9,0))
A27: =Indicators!A14 | B27: =Indicators!C14&" ("&Indicators!B14&")" | C27: =INDEX($B$4:$B$9,MATCH(Indicators!$B14,$A$4:$A$9,0))/INDEX($G$4:$G$9,MATCH(Indicators!$B14,$A$4:$A$9,0)) | D27: =INDEX($C$4:$C$9,MATCH(Indicators!$B14,$A$4:$A$9,0))/INDEX($G$4:$G$9,MATCH(Indicators!$B14,$A$4:$A$9,0)) | E27: =INDEX($D$4:$D$9,MATCH(Indicators!$B14,$A$4:$A$9,0))/INDEX($G$4:$G$9,MATCH(Indicators!$B14,$A$4:$A$9,0)) | F27: =INDEX($E$4:$E$9,MATCH(Indicators!$B14,$A$4:$A$9,0))/INDEX($G$4:$G$9,MATCH(Indicators!$B14,$A$4:$A$9,0)) | G27: =INDEX($F$4:$F$9,MATCH(Indicators!$B14,$A$4:$A$9,0))/INDEX($G$4:$G$9,MATCH(Indicators!$B14,$A$4:$A$9,0))
A28: =Indicators!A15 | B28: =Indicators!C15&" ("&Indicators!B15&")" | C28: =INDEX($B$4:$B$9,MATCH(Indicators!$B15,$A$4:$A$9,0))/INDEX($G$4:$G$9,MATCH(Indicators!$B15,$A$4:$A$9,0)) | D28: =INDEX($C$4:$C$9,MATCH(Indicators!$B15,$A$4:$A$9,0))/INDEX($G$4:$G$9,MATCH(Indicators!$B15,$A$4:$A$9,0)) | E28: =INDEX($D$4:$D$9,MATCH(Indicators!$B15,$A$4:$A$9,0))/INDEX($G$4:$G$9,MATCH(Indicators!$B15,$A$4:$A$9,0)) | F28: =INDEX($E$4:$E$9,MATCH(Indicators!$B15,$A$4:$A$9,0))/INDEX($G$4:$G$9,MATCH(Indicators!$B15,$A$4:$A$9,0)) | G28: =INDEX($F$4:$F$9,MATCH(Indicators!$B15,$A$4:$A$9,0))/INDEX($G$4:$G$9,MATCH(Indicators!$B15,$A$4:$A$9,0))
... A30: =Indicators!A17 | B30: =Indicators!C17&" ("&Indicators!B17&")" | C30: =INDEX($B$4:$B$9,MATCH(Indicators!$B17,$A$4:$A$9,0))/INDEX($G$4:$G$9,MATCH(Indicators!$B17,$A$4:$A$9,0)) | D30: =INDEX($C$4:$C$9,MATCH(Indicators!$B17,$A$4:$A$9,0))/INDEX($G$4:$G$9,MATCH(Indicators!$B17,$A$4:$A$9,0)) | E30: =INDEX($D$4:$D$9,MATCH(Indicators!$B17,$A$4:$A$9,0))/INDEX($G$4:$G$9,MATCH(Indicators!$B17,$A$4:$A$9,0)) | F30: =INDEX($E$4:$E$9,MATCH(Indicators!$B17,$A$4:$A$9,0))/INDEX($G$4:$G$9,MATCH(Indicators!$B17,$A$4:$A$9,0)) | G30: =INDEX($F$4:$F$9,MATCH(Indicators!$B17,$A$4:$A$9,0))/INDEX($G$4:$G$9,MATCH(Indicators!$B17,$A$4:$A$9,0))
B31: Sum | C31: =SUM(C17:C30) | D31: =SUM(D17:D30) | E31: =SUM(E17:E30) | F31: =SUM(F17:F30) | G31: =SUM(G17:G30)

Sheet Indicators
A1: Common indicators, grouped by PESTEL dimension
A2: Proposed by the instructor from the group shortlists. Same for all groups.
A3: ID | B3: PESTEL dimension | C3: Indicator | D3: Julius Meinl dimension | E3: Unit | F3: Direction | G3: Source | H3: Type
A4: P1 | B4: Political | C4: Political stability and absence of violence | D4: Country risk | E4: Estimate, about -2.5 to 2.5 | F4: Higher is better | G4: Worldwide Governance Indicators, World Bank | H4: Quantitative
A5: P2 | B5: Political | C5: Trade agreement between the EU and the country | D5: Import and regulation | E5: Score 1 to 5 (rubric A) | F5: Higher is better | G5: EU Access2Markets | H5: Rubric
A6: E1 | B6: Economic | C6: GDP per capita, PPP | D6: Purchasing power | E6: International dollars | F6: Higher is better | G6: World Development Indicators, World Bank | H6: Quantitative
A7: E2 | B7: Economic | C7: Household final consumption expenditure per capita | D7: Premium coffee segment | E7: US dollars | F7: Higher is better | G7: World Development Indicators, World Bank | H7: Quantitative
A8: E3 | B8: Economic | C8: Inflation, consumer prices | D8: Purchasing power | E8: % per year | F8: Lower is better | G8: World Development Indicators, World Bank | H8: Quantitative
A9: E4 | B9: Economic | C9: Applied tariff on roasted coffee (HS 0901.21), EU origin | D9: Import and regulation | E9: % | F9: Lower is better | G9: EU Access2Markets; WTO tariff data | H9: Quantitative
A10: S1 | B10: Social | C10: Coffee consumption per capita | D10: Coffee culture | E10: Kg per person (check unit) | F10: Higher is better | G10: International Coffee Organization | H10: Quantitative
A11: S2 | B11: Social | C11: International tourist arrivals | D11: Tourism and hotels | E11: Number of arrivals | F11: Higher is better | G11: World Development Indicators (UN Tourism data) | H11: Quantitative
A12: S3 | B12: Social | C12: Cafe culture | D12: Coffee culture | E12: Score 1 to 5 (rubric B) | F12: Higher is better | G12: Own assessment with sources | H12: Rubric
A13: T1 | B13: Technological | C13: Individuals using the Internet | D13: Premium coffee segment | E13: % of population | F13: Higher is better | G13: World Development Indicators, World Bank | H13: Quantitative
A14: T2 | B14: Technological | C14: Logistics Performance Index | D14: Import and regulation | E14: Score 1 to 5 | F14: Higher is better | G14: Logistics Performance Index, World Bank | H14: Quantitative
... A17: L2 | B17: Legal | C17: Product, labelling and certification requirements for coffee | D17: Import and regulation | E17: Score 1 to 5 (rubric D) | F17: Higher is better | G17: EU Access2Markets | H17: Rubric

Sheet Data
A1: Data: each group fills the yellow cells of its own country
D3: Argentina (Group 1) | G3: Brazil (Group 6) | J3: Chile (Group 2) | M3: Colombia (Group 4) | P3: Mexico (Group 3) | S3: Uruguay (Group 5)
A4: ID | B4: Indicator | C4: Direction | D4: Value | E4: Year | F4: Source and link | G4: Value | H4: Year | I4: Source and link | J4: Value | K4: Year | L4: Source and link | M4: Value | N4: Year | O4: Source and link | P4: Value | Q4: Year | R4: Source and link | S4: Value | T4: Year | U4: Source and link
A5: =Indicators!A4 | B5: =Indicators!C4&" ["&Indicators!E4&"]" | C5: =Indicators!F4
A6: =Indicators!A5 | B6: =Indicators!C5&" ["&Indicators!E5&"]" | C6: =Indicators!F5
A7: =Indicators!A6 | B7: =Indicators!C6&" ["&Indicators!E6&"]" | C7: =Indicators!F6
A8: =Indicators!A7 | B8: =Indicators!C7&" ["&Indicators!E7&"]" | C8: =Indicators!F7
A9: =Indicators!A8 | B9: =Indicators!C8&" ["&Indicators!E8&"]" | C9: =Indicators!F8
A10: =Indicators!A9 | B10: =Indicators!C9&" ["&Indicators!E9&"]" | C10: =Indicators!F9
A11: =Indicators!A10 | B11: =Indicators!C10&" ["&Indicators!E10&"]" | C11: =Indicators!F10
A12: =Indicators!A11 | B12: =Indicators!C11&" ["&Indicators!E11&"]" | C12: =Indicators!F11
A13: =Indicators!A12 | B13: =Indicators!C12&" ["&Indicators!E12&"]" | C13: =Indicators!F12
A14: =Indicators!A13 | B14: =Indicators!C13&" ["&Indicators!E13&"]" | C14: =Indicators!F13
A15: =Indicators!A14 | B15: =Indicators!C14&" ["&Indicators!E14&"]" | C15: =Indicators!F14
A16: =Indicators!A15 | B16: =Indicators!C15&" ["&Indicators!E15&"]" | C16: =Indicators!F15
... A18: =Indicators!A17 | B18: =Indicators!C17&" ["&Indicators!E17&"]" | C18: =Indicators!F17

Sheet Normalised
A1: Normalised scores 0 to 100 (min-max, direction respected)
A2: Best country = 100, weakest = 0 on each indicator. Exaggerates small differences with six countries.
A3: ID | B3: Indicator | C3: Argentina | D3: Brazil | E3: Chile | F3: Colombia | G3: Mexico | H3: Uruguay
A4: =Indicators!A4 | B4: =Indicators!C4 | C4: =IF(COUNT(Data!D5,Data!G5,Data!J5,Data!M5,Data!P5,Data!S5)<6,"",IF(MAX(Data!D5,Data!G5,Data!J5,Data!M5,Data!P5,Data!S5)=MIN(Data!D5,Data!G5,Data!J5,Data!M5,Data!P5,Data!S5),"",IF(Data!$C5="Lower is better",100*(MAX(Data!D5,Data!G5,Data!J5,Data!M5,Data!P5,Data!S5)-Data!D5)/(MAX(Data!D5,Data!G5,Data!J5,Data!M5,Data!P5,Data!S5)-MIN(Data!D5,Data!G5,Data!J5,Data!M5,Data!P5,Data!S5)),100*(Data!D5-MIN(Data!D5,Data!G5,Data!J5,Data!M5,Data!P5,Data!S5))/(MAX(Data!D5,Data!G5,Data!J5,Data!M5,Data!P5,Data!S5)-MIN(Data!D5,Data!G5,Data!J5,Data!M5,Data!P5,Data!S5))))) | D4: =IF(COUNT(Data!D5,Data!G5,Data!J5,Data!M5,Data!P5,Data!S5)<6,"",IF(MAX(Data!D5,Data!G5,Data!J5,Data!M5,Data!P5,Data!S5)=MIN(Data!D5,Data!G5,Data!J5,Data!M5,Data!P5,Data!S5),"",IF(Data!$C5="Lower is better",100*(MAX(Data!D5,Data!G5,Data!J5,Data!M5,Data!P5,Data!S5)-Data!G5)/(MAX(Data!D5,Data!G5,Data!J5,Data!M5,Data!P5,Data!S5)-MIN(Data!D5,Data!G5,Data!J5,Data!M5,Data!P5,Data!S5)),100*(Data!G5-MIN(Data!D5,Data!G5,Data!J5,Data!M5,Data!P5,Data!S5))/(MAX(Data!D5,Data!G5,Data!J5,Data!M5,Data!P5,Data!S5)-MIN(Data!D5,Data!G5,Data!J5,Data!M5,Data!P5,Data!S5))))) | E4: =IF(COUNT(Data!D5,Data!G5,Data!J5,Data!M5,Data!P5,Data!S5)<6,"",IF(MAX(Data!D5,Data!G5,Data!J5,Data!M5,Data!P5,Data!S5)=MIN(Data!D5,Data!G5,Data!J5,Data!M5,Data!P5,Data!S5),"",IF(Data!$C5="Lower is better",100*(MAX(Data!D5,Data!G5,Data!J5,Data!M5,Data!P5,Data!S5)-Data!J5)/(MAX(Data!D5,Data!G5,Data!J5,Data!M5,Data!P5,Data!S5)-MIN(Data!D5,Data!G5,Data!J5,Data!M5,Data!P5,Data!S5)),100*(Data!J5-MIN(Data!D5,Data!G5,Data!J5,Data!M5,Data!P5,Data!S5))/(MAX(Data!D5,Data!G5,Data!J5,Data!M5,Data!P5,Data!S5)-MIN(Data!D5,Data!G5,Data!J5,Data!M5,Data!P5,Data!S5))))) | F4: =IF(COUNT(Data!D5,Data!G5,Data!J5,Data!M5,Data!P5,Data!S5)<6,"",IF(MAX(Data!D5,Data!G5,Data!J5,Data!M5,Data!P5,Data!S5)=MIN(Data!D5,Data!G5,Data!J5,Data!M5,Data!P5,Data!S5),"",IF(Data!$C5="Lower is better",100*(MAX(Data!D5,Data!G5,Data!J5,Data!M5,Data!P5,Data!S5)-Data!M5)/(MAX(Data!D5,Data!G5,Data!J5,Data!M5,Data!P5,Data!S5)-MIN(Data!D5,Data!G5,Data!J5,Data!M5,Data!P5,Data!S5)),100*(Data!M5-MIN(Data!D5,Data!G5,Data!J5,Data!M5,Data!P5,Data!S5))/(MAX(Data!D5,Data!G5,Data!J5,Data!M5,Data!P5,Data!S5)-MIN(Data!D5,Data!G5,Data!J5,Data!M5,Data!P5,Data!S5))))) | G4: =IF(COUNT(Data!D5,Data!G5,Data!J5,Data!M5,Data!P5,Data!S5)<6,"",IF(MAX(Data!D5,Data!G5,Data!J5,Data!M5,Data!P5,Data!S5)=MIN(Data!D5,Data!G5,Data!J5,Data!M5,Data!P5,Data!S5),"",IF(Data!$C5="Lower is better",100*(MAX(Data!D5,Data!G5,Data!J5,Data!M5,Data!P5,Data!S5)-Data!P5)/(MAX(Data!D5,Data!G5,Data!J5,Data!M5,Data!P5,Data!S5)-MIN(Data!D5,Data!G5,Data!J5,Data!M5,Data!P5,Data!S5)),100*(Data!P5-MIN(Data!D5,Data!G5,Data!J5,Data!M5,Data!P5,Data!S5))/(MAX(Data!D5,Data!G5,Data!J5,Data!M5,Data!P5,Data!S5)-MIN(Data!D5,Data!G5,Data!J5,Data!M5,Data!P5,Data!S5))))) | H4: =IF(COUNT(Data!D5,Data!G5,Data!J5,Data!M5,Data!P5,Data!S5)<6,"",IF(MAX(Data!D5,Data!G5,Data!J5,Data!M5,Data!P5,Data!S5)=MIN(Data!D5,Data!G5,Data!J5,Data!M5,Data!P5,Data!S5),"",IF(Data!$C5="Lower is better",100*(MAX(Data!D5,Data!G5,Data!J5,Data!M5,Data!P5,Data!S5)-Data!S5)/(MAX(Data!D5,Data!G5,Data!J5,Data!M5,Data!P5,Data!S5)-MIN(Data!D5,Data!G5,Data!J5,Data!M5,Data!P5,Data!S5)),100*(Data!S5-MIN(Data!D5,Data!G5,Data!J5,Data!M5,Data!P5,Data!S5))/(MAX(Data!D5,Data!G5,Data!J5,Data!M5,Data!P5,Data!S5)-MIN(Data!D5,Data!G5,Data!J5,Data!M5,Data!P5,Data!S5)))))
A5: =Indicators!A5 | B5: =Indicators!C5 | C5: =IF(COUNT(Data!D6,Data!G6,Data!J6,Data!M6,Data!P6,Data!S6)<6,"",IF(MAX(Data!D6,Data!G6,Data!J6,Data!M6,Data!P6,Data!S6)=MIN(Data!D6,Data!G6,Data!J6,Data!M6,Data!P6,Data!S6),"",IF(Data!$C6="Lower is better",100*(MAX(Data!D6,Data!G6,Data!J6,Data!M6,Data!P6,Data!S6)-Data!D6)/(MAX(Data!D6,Data!G6,Data!J6,Data!M6,Data!P6,Data!S6)-MIN(Data!D6,Data!G6,Data!J6,Data!M6,Data!P6,Data!S6)),100*(Data!D6-MIN(Data!D6,Data!G6,Data!J6,Data!M6,Data!P6,Data!S6))/(MAX(Data!D6,Data!G6,Data!J6,Data!M6,Data!P6,Data!S6)-MIN(Data!D6,Data!G6,Data!J6,Data!M6,Data!P6,Data!S6))))) | D5: =IF(COUNT(Data!D6,Data!G6,Data!J6,Data!M6,Data!P6,Data!S6)<6,"",IF(MAX(Data!D6,Data!G6,Data!J6,Data!M6,Data!P6,Data!S6)=MIN(Data!D6,Data!G6,Data!J6,Data!M6,Data!P6,Data!S6),"",IF(Data!$C6="Lower is better",100*(MAX(Data!D6,Data!G6,Data!J6,Data!M6,Data!P6,Data!S6)-Data!G6)/(MAX(Data!D6,Data!G6,Data!J6,Data!M6,Data!P6,Data!S6)-MIN(Data!D6,Data!G6,Data!J6,Data!M6,Data!P6,Data!S6)),100*(Data!G6-MIN(Data!D6,Data!G6,Data!J6,Data!M6,Data!P6,Data!S6))/(MAX(Data!D6,Data!G6,Data!J6,Data!M6,Data!P6,Data!S6)-MIN(Data!D6,Data!G6,Data!J6,Data!M6,Data!P6,Data!S6))))) | E5: =IF(COUNT(Data!D6,Data!G6,Data!J6,Data!M6,Data!P6,Data!S6)<6,"",IF(MAX(Data!D6,Data!G6,Data!J6,Data!M6,Data!P6,Data!S6)=MIN(Data!D6,Data!G6,Data!J6,Data!M6,Data!P6,Data!S6),"",IF(Data!$C6="Lower is better",100*(MAX(Data!D6,Data!G6,Data!J6,Data!M6,Data!P6,Data!S6)-Data!J6)/(MAX(Data!D6,Data!G6,Data!J6,Data!M6,Data!P6,Data!S6)-MIN(Data!D6,Data!G6,Data!J6,Data!M6,Data!P6,Data!S6)),100*(Data!J6-MIN(Data!D6,Data!G6,Data!J6,Data!M6,Data!P6,Data!S6))/(MAX(Data!D6,Data!G6,Data!J6,Data!M6,Data!P6,Data!S6)-MIN(Data!D6,Data!G6,Data!J6,Data!M6,Data!P6,Data!S6))))) | F5: =IF(COUNT(Data!D6,Data!G6,Data!J6,Data!M6,Data!P6,Data!S6)<6,"",IF(MAX(Data!D6,Data!G6,Data!J6,Data!M6,Data!P6,Data!S6)=MIN(Data!D6,Data!G6,Data!J6,Data!M6,Data!P6,Data!S6),"",IF(Data!$C6="Lower is better",100*(MAX(Data!D6,Data!G6,Data!J6,Data!M6,Data!P6,Data!S6)-Data!M6)/(MAX(Data!D6,Data!G6,Data!J6,Data!M6,Data!P6,Data!S6)-MIN(Data!D6,Data!G6,Data!J6,Data!M6,Data!P6,Data!S6)),100*(Data!M6-MIN(Data!D6,Data!G6,Data!J6,Data!M6,Data!P6,Data!S6))/(MAX(Data!D6,Data!G6,Data!J6,Data!M6,Data!P6,Data!S6)-MIN(Data!D6,Data!G6,Data!J6,Data!M6,Data!P6,Data!S6))))) | G5: =IF(COUNT(Data!D6,Data!G6,Data!J6,Data!M6,Data!P6,Data!S6)<6,"",IF(MAX(Data!D6,Data!G6,Data!J6,Data!M6,Data!P6,Data!S6)=MIN(Data!D6,Data!G6,Data!J6,Data!M6,Data!P6,Data!S6),"",IF(Data!$C6="Lower is better",100*(MAX(Data!D6,Data!G6,Data!J6,Data!M6,Data!P6,Data!S6)-Data!P6)/(MAX(Data!D6,Data!G6,Data!J6,Data!M6,Data!P6,Data!S6)-MIN(Data!D6,Data!G6,Data!J6,Data!M6,Data!P6,Data!S6)),100*(Data!P6-MIN(Data!D6,Data!G6,Data!J6,Data!M6,Data!P6,Data!S6))/(MAX(Data!D6,Data!G6,Data!J6,Data!M6,Data!P6,Data!S6)-MIN(Data!D6,Data!G6,Data!J6,Data!M6,Data!P6,Data!S6))))) | H5: =IF(COUNT(Data!D6,Data!G6,Data!J6,Data!M6,Data!P6,Data!S6)<6,"",IF(MAX(Data!D6,Data!G6,Data!J6,Data!M6,Data!P6,Data!S6)=MIN(Data!D6,Data!G6,Data!J6,Data!M6,Data!P6,Data!S6),"",IF(Data!$C6="Lower is better",100*(MAX(Data!D6,Data!G6,Data!J6,Data!M6,Data!P6,Data!S6)-Data!S6)/(MAX(Data!D6,Data!G6,Data!J6,Data!M6,Data!P6,Data!S6)-MIN(Data!D6,Data!G6,Data!J6,Data!M6,Data!P6,Data!S6)),100*(Data!S6-MIN(Data!D6,Data!G6,Data!J6,Data!M6,Data!P6,Data!S6))/(MAX(Data!D6,Data!G6,Data!J6,Data!M6,Data!P6,Data!S6)-MIN(Data!D6,Data!G6,Data!J6,Data!M6,Data!P6,Data!S6)))))
A6: =Indicators!A6 | B6: =Indicators!C6 | C6: =IF(COUNT(Data!D7,Data!G7,Data!J7,Data!M7,Data!P7,Data!S7)<6,"",IF(MAX(Data!D7,Data!G7,Data!J7,Data!M7,Data!P7,Data!S7)=MIN(Data!D7,Data!G7,Data!J7,Data!M7,Data!P7,Data!S7),"",IF(Data!$C7="Lower is better",100*(MAX(Data!D7,Data!G7,Data!J7,Data!M7,Data!P7,Data!S7)-Data!D7)/(MAX(Data!D7,Data!G7,Data!J7,Data!M7,Data!P7,Data!S7)-MIN(Data!D7,Data!G7,Data!J7,Data!M7,Data!P7,Data!S7)),100*(Data!D7-MIN(Data!D7,Data!G7,Data!J7,Data!M7,Data!P7,Data!S7))/(MAX(Data!D7,Data!G7,Data!J7,Data!M7,Data!P7,Data!S7)-MIN(Data!D7,Data!G7,Data!J7,Data!M7,Data!P7,Data!S7))))) | D6: =IF(COUNT(Data!D7,Data!G7,Data!J7,Data!M7,Data!P7,Data!S7)<6,"",IF(MAX(Data!D7,Data!G7,Data!J7,Data!M7,Data!P7,Data!S7)=MIN(Data!D7,Data!G7,Data!J7,Data!M7,Data!P7,Data!S7),"",IF(Data!$C7="Lower is better",100*(MAX(Data!D7,Data!G7,Data!J7,Data!M7,Data!P7,Data!S7)-Data!G7)/(MAX(Data!D7,Data!G7,Data!J7,Data!M7,Data!P7,Data!S7)-MIN(Data!D7,Data!G7,Data!J7,Data!M7,Data!P7,Data!S7)),100*(Data!G7-MIN(Data!D7,Data!G7,Data!J7,Data!M7,Data!P7,Data!S7))/(MAX(Data!D7,Data!G7,Data!J7,Data!M7,Data!P7,Data!S7)-MIN(Data!D7,Data!G7,Data!J7,Data!M7,Data!P7,Data!S7))))) | E6: =IF(COUNT(Data!D7,Data!G7,Data!J7,Data!M7,Data!P7,Data!S7)<6,"",IF(MAX(Data!D7,Data!G7,Data!J7,Data!M7,Data!P7,Data!S7)=MIN(Data!D7,Data!G7,Data!J7,Data!M7,Data!P7,Data!S7),"",IF(Data!$C7="Lower is better",100*(MAX(Data!D7,Data!G7,Data!J7,Data!M7,Data!P7,Data!S7)-Data!J7)/(MAX(Data!D7,Data!G7,Data!J7,Data!M7,Data!P7,Data!S7)-MIN(Data!D7,Data!G7,Data!J7,Data!M7,Data!P7,Data!S7)),100*(Data!J7-MIN(Data!D7,Data!G7,Data!J7,Data!M7,Data!P7,Data!S7))/(MAX(Data!D7,Data!G7,Data!J7,Data!M7,Data!P7,Data!S7)-MIN(Data!D7,Data!G7,Data!J7,Data!M7,Data!P7,Data!S7))))) | F6: =IF(COUNT(Data!D7,Data!G7,Data!J7,Data!M7,Data!P7,Data!S7)<6,"",IF(MAX(Data!D7,Data!G7,Data!J7,Data!M7,Data!P7,Data!S7)=MIN(Data!D7,Data!G7,Data!J7,Data!M7,Data!P7,Data!S7),"",IF(Data!$C7="Lower is better",100*(MAX(Data!D7,Data!G7,Data!J7,Data!M7,Data!P7,Data!S7)-Data!M7)/(MAX(Data!D7,Data!G7,Data!J7,Data!M7,Data!P7,Data!S7)-MIN(Data!D7,Data!G7,Data!J7,Data!M7,Data!P7,Data!S7)),100*(Data!M7-MIN(Data!D7,Data!G7,Data!J7,Data!M7,Data!P7,Data!S7))/(MAX(Data!D7,Data!G7,Data!J7,Data!M7,Data!P7,Data!S7)-MIN(Data!D7,Data!G7,Data!J7,Data!M7,Data!P7,Data!S7))))) | G6: =IF(COUNT(Data!D7,Data!G7,Data!J7,Data!M7,Data!P7,Data!S7)<6,"",IF(MAX(Data!D7,Data!G7,Data!J7,Data!M7,Data!P7,Data!S7)=MIN(Data!D7,Data!G7,Data!J7,Data!M7,Data!P7,Data!S7),"",IF(Data!$C7="Lower is better",100*(MAX(Data!D7,Data!G7,Data!J7,Data!M7,Data!P7,Data!S7)-Data!P7)/(MAX(Data!D7,Data!G7,Data!J7,Data!M7,Data!P7,Data!S7)-MIN(Data!D7,Data!G7,Data!J7,Data!M7,Data!P7,Data!S7)),100*(Data!P7-MIN(Data!D7,Data!G7,Data!J7,Data!M7,Data!P7,Data!S7))/(MAX(Data!D7,Data!G7,Data!J7,Data!M7,Data!P7,Data!S7)-MIN(Data!D7,Data!G7,Data!J7,Data!M7,Data!P7,Data!S7))))) | H6: =IF(COUNT(Data!D7,Data!G7,Data!J7,Data!M7,Data!P7,Data!S7)<6,"",IF(MAX(Data!D7,Data!G7,Data!J7,Data!M7,Data!P7,Data!S7)=MIN(Data!D7,Data!G7,Data!J7,Data!M7,Data!P7,Data!S7),"",IF(Data!$C7="Lower is better",100*(MAX(Data!D7,Data!G7,Data!J7,Data!M7,Data!P7,Data!S7)-Data!S7)/(MAX(Data!D7,Data!G7,Data!J7,Data!M7,Data!P7,Data!S7)-MIN(Data!D7,Data!G7,Data!J7,Data!M7,Data!P7,Data!S7)),100*(Data!S7-MIN(Data!D7,Data!G7,Data!J7,Data!M7,Data!P7,Data!S7))/(MAX(Data!D7,Data!G7,Data!J7,Data!M7,Data!P7,Data!S7)-MIN(Data!D7,Data!G7,Data!J7,Data!M7,Data!P7,Data!S7)))))
A7: =Indicators!A7 | B7: =Indicators!C7 | C7: =IF(COUNT(Data!D8,Data!G8,Data!J8,Data!M8,Data!P8,Data!S8)<6,"",IF(MAX(Data!D8,Data!G8,Data!J8,Data!M8,Data!P8,Data!S8)=MIN(Data!D8,Data!G8,Data!J8,Data!M8,Data!P8,Data!S8),"",IF(Data!$C8="Lower is better",100*(MAX(Data!D8,Data!G8,Data!J8,Data!M8,Data!P8,Data!S8)-Data!D8)/(MAX(Data!D8,Data!G8,Data!J8,Data!M8,Data!P8,Data!S8)-MIN(Data!D8,Data!G8,Data!J8,Data!M8,Data!P8,Data!S8)),100*(Data!D8-MIN(Data!D8,Data!G8,Data!J8,Data!M8,Data!P8,Data!S8))/(MAX(Data!D8,Data!G8,Data!J8,Data!M8,Data!P8,Data!S8)-MIN(Data!D8,Data!G8,Data!J8,Data!M8,Data!P8,Data!S8))))) | D7: =IF(COUNT(Data!D8,Data!G8,Data!J8,Data!M8,Data!P8,Data!S8)<6,"",IF(MAX(Data!D8,Data!G8,Data!J8,Data!M8,Data!P8,Data!S8)=MIN(Data!D8,Data!G8,Data!J8,Data!M8,Data!P8,Data!S8),"",IF(Data!$C8="Lower is better",100*(MAX(Data!D8,Data!G8,Data!J8,Data!M8,Data!P8,Data!S8)-Data!G8)/(MAX(Data!D8,Data!G8,Data!J8,Data!M8,Data!P8,Data!S8)-MIN(Data!D8,Data!G8,Data!J8,Data!M8,Data!P8,Data!S8)),100*(Data!G8-MIN(Data!D8,Data!G8,Data!J8,Data!M8,Data!P8,Data!S8))/(MAX(Data!D8,Data!G8,Data!J8,Data!M8,Data!P8,Data!S8)-MIN(Data!D8,Data!G8,Data!J8,Data!M8,Data!P8,Data!S8))))) | E7: =IF(COUNT(Data!D8,Data!G8,Data!J8,Data!M8,Data!P8,Data!S8)<6,"",IF(MAX(Data!D8,Data!G8,Data!J8,Data!M8,Data!P8,Data!S8)=MIN(Data!D8,Data!G8,Data!J8,Data!M8,Data!P8,Data!S8),"",IF(Data!$C8="Lower is better",100*(MAX(Data!D8,Data!G8,Data!J8,Data!M8,Data!P8,Data!S8)-Data!J8)/(MAX(Data!D8,Data!G8,Data!J8,Data!M8,Data!P8,Data!S8)-MIN(Data!D8,Data!G8,Data!J8,Data!M8,Data!P8,Data!S8)),100*(Data!J8-MIN(Data!D8,Data!G8,Data!J8,Data!M8,Data!P8,Data!S8))/(MAX(Data!D8,Data!G8,Data!J8,Data!M8,Data!P8,Data!S8)-MIN(Data!D8,Data!G8,Data!J8,Data!M8,Data!P8,Data!S8))))) | F7: =IF(COUNT(Data!D8,Data!G8,Data!J8,Data!M8,Data!P8,Data!S8)<6,"",IF(MAX(Data!D8,Data!G8,Data!J8,Data!M8,Data!P8,Data!S8)=MIN(Data!D8,Data!G8,Data!J8,Data!M8,Data!P8,Data!S8),"",IF(Data!$C8="Lower is better",100*(MAX(Data!D8,Data!G8,Data!J8,Data!M8,Data!P8,Data!S8)-Data!M8)/(MAX(Data!D8,Data!G8,Data!J8,Data!M8,Data!P8,Data!S8)-MIN(Data!D8,Data!G8,Data!J8,Data!M8,Data!P8,Data!S8)),100*(Data!M8-MIN(Data!D8,Data!G8,Data!J8,Data!M8,Data!P8,Data!S8))/(MAX(Data!D8,Data!G8,Data!J8,Data!M8,Data!P8,Data!S8)-MIN(Data!D8,Data!G8,Data!J8,Data!M8,Data!P8,Data!S8))))) | G7: =IF(COUNT(Data!D8,Data!G8,Data!J8,Data!M8,Data!P8,Data!S8)<6,"",IF(MAX(Data!D8,Data!G8,Data!J8,Data!M8,Data!P8,Data!S8)=MIN(Data!D8,Data!G8,Data!J8,Data!M8,Data!P8,Data!S8),"",IF(Data!$C8="Lower is better",100*(MAX(Data!D8,Data!G8,Data!J8,Data!M8,Data!P8,Data!S8)-Data!P8)/(MAX(Data!D8,Data!G8,Data!J8,Data!M8,Data!P8,Data!S8)-MIN(Data!D8,Data!G8,Data!J8,Data!M8,Data!P8,Data!S8)),100*(Data!P8-MIN(Data!D8,Data!G8,Data!J8,Data!M8,Data!P8,Data!S8))/(MAX(Data!D8,Data!G8,Data!J8,Data!M8,Data!P8,Data!S8)-MIN(Data!D8,Data!G8,Data!J8,Data!M8,Data!P8,Data!S8))))) | H7: =IF(COUNT(Data!D8,Data!G8,Data!J8,Data!M8,Data!P8,Data!S8)<6,"",IF(MAX(Data!D8,Data!G8,Data!J8,Data!M8,Data!P8,Data!S8)=MIN(Data!D8,Data!G8,Data!J8,Data!M8,Data!P8,Data!S8),"",IF(Data!$C8="Lower is better",100*(MAX(Data!D8,Data!G8,Data!J8,Data!M8,Data!P8,Data!S8)-Data!S8)/(MAX(Data!D8,Data!G8,Data!J8,Data!M8,Data!P8,Data!S8)-MIN(Data!D8,Data!G8,Data!J8,Data!M8,Data!P8,Data!S8)),100*(Data!S8-MIN(Data!D8,Data!G8,Data!J8,Data!M8,Data!P8,Data!S8))/(MAX(Data!D8,Data!G8,Data!J8,Data!M8,Data!P8,Data!S8)-MIN(Data!D8,Data!G8,Data!J8,Data!M8,Data!P8,Data!S8)))))
A8: =Indicators!A8 | B8: =Indicators!C8 | C8: =IF(COUNT(Data!D9,Data!G9,Data!J9,Data!M9,Data!P9,Data!S9)<6,"",IF(MAX(Data!D9,Data!G9,Data!J9,Data!M9,Data!P9,Data!S9)=MIN(Data!D9,Data!G9,Data!J9,Data!M9,Data!P9,Data!S9),"",IF(Data!$C9="Lower is better",100*(MAX(Data!D9,Data!G9,Data!J9,Data!M9,Data!P9,Data!S9)-Data!D9)/(MAX(Data!D9,Data!G9,Data!J9,Data!M9,Data!P9,Data!S9)-MIN(Data!D9,Data!G9,Data!J9,Data!M9,Data!P9,Data!S9)),100*(Data!D9-MIN(Data!D9,Data!G9,Data!J9,Data!M9,Data!P9,Data!S9))/(MAX(Data!D9,Data!G9,Data!J9,Data!M9,Data!P9,Data!S9)-MIN(Data!D9,Data!G9,Data!J9,Data!M9,Data!P9,Data!S9))))) | D8: =IF(COUNT(Data!D9,Data!G9,Data!J9,Data!M9,Data!P9,Data!S9)<6,"",IF(MAX(Data!D9,Data!G9,Data!J9,Data!M9,Data!P9,Data!S9)=MIN(Data!D9,Data!G9,Data!J9,Data!M9,Data!P9,Data!S9),"",IF(Data!$C9="Lower is better",100*(MAX(Data!D9,Data!G9,Data!J9,Data!M9,Data!P9,Data!S9)-Data!G9)/(MAX(Data!D9,Data!G9,Data!J9,Data!M9,Data!P9,Data!S9)-MIN(Data!D9,Data!G9,Data!J9,Data!M9,Data!P9,Data!S9)),100*(Data!G9-MIN(Data!D9,Data!G9,Data!J9,Data!M9,Data!P9,Data!S9))/(MAX(Data!D9,Data!G9,Data!J9,Data!M9,Data!P9,Data!S9)-MIN(Data!D9,Data!G9,Data!J9,Data!M9,Data!P9,Data!S9))))) | E8: =IF(COUNT(Data!D9,Data!G9,Data!J9,Data!M9,Data!P9,Data!S9)<6,"",IF(MAX(Data!D9,Data!G9,Data!J9,Data!M9,Data!P9,Data!S9)=MIN(Data!D9,Data!G9,Data!J9,Data!M9,Data!P9,Data!S9),"",IF(Data!$C9="Lower is better",100*(MAX(Data!D9,Data!G9,Data!J9,Data!M9,Data!P9,Data!S9)-Data!J9)/(MAX(Data!D9,Data!G9,Data!J9,Data!M9,Data!P9,Data!S9)-MIN(Data!D9,Data!G9,Data!J9,Data!M9,Data!P9,Data!S9)),100*(Data!J9-MIN(Data!D9,Data!G9,Data!J9,Data!M9,Data!P9,Data!S9))/(MAX(Data!D9,Data!G9,Data!J9,Data!M9,Data!P9,Data!S9)-MIN(Data!D9,Data!G9,Data!J9,Data!M9,Data!P9,Data!S9))))) | F8: =IF(COUNT(Data!D9,Data!G9,Data!J9,Data!M9,Data!P9,Data!S9)<6,"",IF(MAX(Data!D9,Data!G9,Data!J9,Data!M9,Data!P9,Data!S9)=MIN(Data!D9,Data!G9,Data!J9,Data!M9,Data!P9,Data!S9),"",IF(Data!$C9="Lower is better",100*(MAX(Data!D9,Data!G9,Data!J9,Data!M9,Data!P9,Data!S9)-Data!M9)/(MAX(Data!D9,Data!G9,Data!J9,Data!M9,Data!P9,Data!S9)-MIN(Data!D9,Data!G9,Data!J9,Data!M9,Data!P9,Data!S9)),100*(Data!M9-MIN(Data!D9,Data!G9,Data!J9,Data!M9,Data!P9,Data!S9))/(MAX(Data!D9,Data!G9,Data!J9,Data!M9,Data!P9,Data!S9)-MIN(Data!D9,Data!G9,Data!J9,Data!M9,Data!P9,Data!S9))))) | G8: =IF(COUNT(Data!D9,Data!G9,Data!J9,Data!M9,Data!P9,Data!S9)<6,"",IF(MAX(Data!D9,Data!G9,Data!J9,Data!M9,Data!P9,Data!S9)=MIN(Data!D9,Data!G9,Data!J9,Data!M9,Data!P9,Data!S9),"",IF(Data!$C9="Lower is better",100*(MAX(Data!D9,Data!G9,Data!J9,Data!M9,Data!P9,Data!S9)-Data!P9)/(MAX(Data!D9,Data!G9,Data!J9,Data!M9,Data!P9,Data!S9)-MIN(Data!D9,Data!G9,Data!J9,Data!M9,Data!P9,Data!S9)),100*(Data!P9-MIN(Data!D9,Data!G9,Data!J9,Data!M9,Data!P9,Data!S9))/(MAX(Data!D9,Data!G9,Data!J9,Data!M9,Data!P9,Data!S9)-MIN(Data!D9,Data!G9,Data!J9,Data!M9,Data!P9,Data!S9))))) | H8: =IF(COUNT(Data!D9,Data!G9,Data!J9,Data!M9,Data!P9,Data!S9)<6,"",IF(MAX(Data!D9,Data!G9,Data!J9,Data!M9,Data!P9,Data!S9)=MIN(Data!D9,Data!G9,Data!J9,Data!M9,Data!P9,Data!S9),"",IF(Data!$C9="Lower is better",100*(MAX(Data!D9,Data!G9,Data!J9,Data!M9,Data!P9,Data!S9)-Data!S9)/(MAX(Data!D9,Data!G9,Data!J9,Data!M9,Data!P9,Data!S9)-MIN(Data!D9,Data!G9,Data!J9,Data!M9,Data!P9,Data!S9)),100*(Data!S9-MIN(Data!D9,Data!G9,Data!J9,Data!M9,Data!P9,Data!S9))/(MAX(Data!D9,Data!G9,Data!J9,Data!M9,Data!P9,Data!S9)-MIN(Data!D9,Data!G9,Data!J9,Data!M9,Data!P9,Data!S9)))))
A9: =Indicators!A9 | B9: =Indicators!C9 | C9: =IF(COUNT(Data!D10,Data!G10,Data!J10,Data!M10,Data!P10,Data!S10)<6,"",IF(MAX(Data!D10,Data!G10,Data!J10,Data!M10,Data!P10,Data!S10)=MIN(Data!D10,Data!G10,Data!J10,Data!M10,Data!P10,Data!S10),"",IF(Data!$C10="Lower is better",100*(MAX(Data!D10,Data!G10,Data!J10,Data!M10,Data!P10,Data!S10)-Data!D10)/(MAX(Data!D10,Data!G10,Data!J10,Data!M10,Data!P10,Data!S10)-MIN(Data!D10,Data!G10,Data!J10,Data!M10,Data!P10,Data!S10)),100*(Data!D10-MIN(Data!D10,Data!G10,Data!J10,Data!M10,Data!P10,Data!S10))/(MAX(Data!D10,Data!G10,Data!J10,Data!M10,Data!P10,Data!S10)-MIN(Data!D10,Data!G10,Data!J10,Data!M10,Data!P10,Data!S10))))) | D9: =IF(COUNT(Data!D10,Data!G10,Data!J10,Data!M10,Data!P10,Data!S10)<6,"",IF(MAX(Data!D10,Data!G10,Data!J10,Data!M10,Data!P10,Data!S10)=MIN(Data!D10,Data!G10,Data!J10,Data!M10,Data!P10,Data!S10),"",IF(Data!$C10="Lower is better",100*(MAX(Data!D10,Data!G10,Data!J10,Data!M10,Data!P10,Data!S10)-Data!G10)/(MAX(Data!D10,Data!G10,Data!J10,Data!M10,Data!P10,Data!S10)-MIN(Data!D10,Data!G10,Data!J10,Data!M10,Data!P10,Data!S10)),100*(Data!G10-MIN(Data!D10,Data!G10,Data!J10,Data!M10,Data!P10,Data!S10))/(MAX(Data!D10,Data!G10,Data!J10,Data!M10,Data!P10,Data!S10)-MIN(Data!D10,Data!G10,Data!J10,Data!M10,Data!P10,Data!S10))))) | E9: =IF(COUNT(Data!D10,Data!G10,Data!J10,Data!M10,Data!P10,Data!S10)<6,"",IF(MAX(Data!D10,Data!G10,Data!J10,Data!M10,Data!P10,Data!S10)=MIN(Data!D10,Data!G10,Data!J10,Data!M10,Data!P10,Data!S10),"",IF(Data!$C10="Lower is better",100*(MAX(Data!D10,Data!G10,Data!J10,Data!M10,Data!P10,Data!S10)-Data!J10)/(MAX(Data!D10,Data!G10,Data!J10,Data!M10,Data!P10,Data!S10)-MIN(Data!D10,Data!G10,Data!J10,Data!M10,Data!P10,Data!S10)),100*(Data!J10-MIN(Data!D10,Data!G10,Data!J10,Data!M10,Data!P10,Data!S10))/(MAX(Data!D10,Data!G10,Data!J10,Data!M10,Data!P10,Data!S10)-MIN(Data!D10,Data!G10,Data!J10,Data!M10,Data!P10,Data!S10))))) | F9: =IF(COUNT(Data!D10,Data!G10,Data!J10,Data!M10,Data!P10,Data!S10)<6,"",IF(MAX(Data!D10,Data!G10,Data!J10,Data!M10,Data!P10,Data!S10)=MIN(Data!D10,Data!G10,Data!J10,Data!M10,Data!P10,Data!S10),"",IF(Data!$C10="Lower is better",100*(MAX(Data!D10,Data!G10,Data!J10,Data!M10,Data!P10,Data!S10)-Data!M10)/(MAX(Data!D10,Data!G10,Data!J10,Data!M10,Data!P10,Data!S10)-MIN(Data!D10,Data!G10,Data!J10,Data!M10,Data!P10,Data!S10)),100*(Data!M10-MIN(Data!D10,Data!G10,Data!J10,Data!M10,Data!P10,Data!S10))/(MAX(Data!D10,Data!G10,Data!J10,Data!M10,Data!P10,Data!S10)-MIN(Data!D10,Data!G10,Data!J10,Data!M10,Data!P10,Data!S10))))) | G9: =IF(COUNT(Data!D10,Data!G10,Data!J10,Data!M10,Data!P10,Data!S10)<6,"",IF(MAX(Data!D10,Data!G10,Data!J10,Data!M10,Data!P10,Data!S10)=MIN(Data!D10,Data!G10,Data!J10,Data!M10,Data!P10,Data!S10),"",IF(Data!$C10="Lower is better",100*(MAX(Data!D10,Data!G10,Data!J10,Data!M10,Data!P10,Data!S10)-Data!P10)/(MAX(Data!D10,Data!G10,Data!J10,Data!M10,Data!P10,Data!S10)-MIN(Data!D10,Data!G10,Data!J10,Data!M10,Data!P10,Data!S10)),100*(Data!P10-MIN(Data!D10,Data!G10,Data!J10,Data!M10,Data!P10,Data!S10))/(MAX(Data!D10,Data!G10,Data!J10,Data!M10,Data!P10,Data!S10)-MIN(Data!D10,Data!G10,Data!J10,Data!M10,Data!P10,Data!S10))))) | H9: =IF(COUNT(Data!D10,Data!G10,Data!J10,Data!M10,Data!P10,Data!S10)<6,"",IF(MAX(Data!D10,Data!G10,Data!J10,Data!M10,Data!P10,Data!S10)=MIN(Data!D10,Data!G10,Data!J10,Data!M10,Data!P10,Data!S10),"",IF(Data!$C10="Lower is better",100*(MAX(Data!D10,Data!G10,Data!J10,Data!M10,Data!P10,Data!S10)-Data!S10)/(MAX(Data!D10,Data!G10,Data!J10,Data!M10,Data!P10,Data!S10)-MIN(Data!D10,Data!G10,Data!J10,Data!M10,Data!P10,Data!S10)),100*(Data!S10-MIN(Data!D10,Data!G10,Data!J10,Data!M10,Data!P10,Data!S10))/(MAX(Data!D10,Data!G10,Data!J10,Data!M10,Data!P10,Data!S10)-MIN(Data!D10,Data!G10,Data!J10,Data!M10,Data!P10,Data!S10)))))
A10: =Indicators!A10 | B10: =Indicators!C10 | C10: =IF(COUNT(Data!D11,Data!G11,Data!J11,Data!M11,Data!P11,Data!S11)<6,"",IF(MAX(Data!D11,Data!G11,Data!J11,Data!M11,Data!P11,Data!S11)=MIN(Data!D11,Data!G11,Data!J11,Data!M11,Data!P11,Data!S11),"",IF(Data!$C11="Lower is better",100*(MAX(Data!D11,Data!G11,Data!J11,Data!M11,Data!P11,Data!S11)-Data!D11)/(MAX(Data!D11,Data!G11,Data!J11,Data!M11,Data!P11,Data!S11)-MIN(Data!D11,Data!G11,Data!J11,Data!M11,Data!P11,Data!S11)),100*(Data!D11-MIN(Data!D11,Data!G11,Data!J11,Data!M11,Data!P11,Data!S11))/(MAX(Data!D11,Data!G11,Data!J11,Data!M11,Data!P11,Data!S11)-MIN(Data!D11,Data!G11,Data!J11,Data!M11,Data!P11,Data!S11))))) | D10: =IF(COUNT(Data!D11,Data!G11,Data!J11,Data!M11,Data!P11,Data!S11)<6,"",IF(MAX(Data!D11,Data!G11,Data!J11,Data!M11,Data!P11,Data!S11)=MIN(Data!D11,Data!G11,Data!J11,Data!M11,Data!P11,Data!S11),"",IF(Data!$C11="Lower is better",100*(MAX(Data!D11,Data!G11,Data!J11,Data!M11,Data!P11,Data!S11)-Data!G11)/(MAX(Data!D11,Data!G11,Data!J11,Data!M11,Data!P11,Data!S11)-MIN(Data!D11,Data!G11,Data!J11,Data!M11,Data!P11,Data!S11)),100*(Data!G11-MIN(Data!D11,Data!G11,Data!J11,Data!M11,Data!P11,Data!S11))/(MAX(Data!D11,Data!G11,Data!J11,Data!M11,Data!P11,Data!S11)-MIN(Data!D11,Data!G11,Data!J11,Data!M11,Data!P11,Data!S11))))) | E10: =IF(COUNT(Data!D11,Data!G11,Data!J11,Data!M11,Data!P11,Data!S11)<6,"",IF(MAX(Data!D11,Data!G11,Data!J11,Data!M11,Data!P11,Data!S11)=MIN(Data!D11,Data!G11,Data!J11,Data!M11,Data!P11,Data!S11),"",IF(Data!$C11="Lower is better",100*(MAX(Data!D11,Data!G11,Data!J11,Data!M11,Data!P11,Data!S11)-Data!J11)/(MAX(Data!D11,Data!G11,Data!J11,Data!M11,Data!P11,Data!S11)-MIN(Data!D11,Data!G11,Data!J11,Data!M11,Data!P11,Data!S11)),100*(Data!J11-MIN(Data!D11,Data!G11,Data!J11,Data!M11,Data!P11,Data!S11))/(MAX(Data!D11,Data!G11,Data!J11,Data!M11,Data!P11,Data!S11)-MIN(Data!D11,Data!G11,Data!J11,Data!M11,Data!P11,Data!S11))))) | F10: =IF(COUNT(Data!D11,Data!G11,Data!J11,Data!M11,Data!P11,Data!S11)<6,"",IF(MAX(Data!D11,Data!G11,Data!J11,Data!M11,Data!P11,Data!S11)=MIN(Data!D11,Data!G11,Data!J11,Data!M11,Data!P11,Data!S11),"",IF(Data!$C11="Lower is better",100*(MAX(Data!D11,Data!G11,Data!J11,Data!M11,Data!P11,Data!S11)-Data!M11)/(MAX(Data!D11,Data!G11,Data!J11,Data!M11,Data!P11,Data!S11)-MIN(Data!D11,Data!G11,Data!J11,Data!M11,Data!P11,Data!S11)),100*(Data!M11-MIN(Data!D11,Data!G11,Data!J11,Data!M11,Data!P11,Data!S11))/(MAX(Data!D11,Data!G11,Data!J11,Data!M11,Data!P11,Data!S11)-MIN(Data!D11,Data!G11,Data!J11,Data!M11,Data!P11,Data!S11))))) | G10: =IF(COUNT(Data!D11,Data!G11,Data!J11,Data!M11,Data!P11,Data!S11)<6,"",IF(MAX(Data!D11,Data!G11,Data!J11,Data!M11,Data!P11,Data!S11)=MIN(Data!D11,Data!G11,Data!J11,Data!M11,Data!P11,Data!S11),"",IF(Data!$C11="Lower is better",100*(MAX(Data!D11,Data!G11,Data!J11,Data!M11,Data!P11,Data!S11)-Data!P11)/(MAX(Data!D11,Data!G11,Data!J11,Data!M11,Data!P11,Data!S11)-MIN(Data!D11,Data!G11,Data!J11,Data!M11,Data!P11,Data!S11)),100*(Data!P11-MIN(Data!D11,Data!G11,Data!J11,Data!M11,Data!P11,Data!S11))/(MAX(Data!D11,Data!G11,Data!J11,Data!M11,Data!P11,Data!S11)-MIN(Data!D11,Data!G11,Data!J11,Data!M11,Data!P11,Data!S11))))) | H10: =IF(COUNT(Data!D11,Data!G11,Data!J11,Data!M11,Data!P11,Data!S11)<6,"",IF(MAX(Data!D11,Data!G11,Data!J11,Data!M11,Data!P11,Data!S11)=MIN(Data!D11,Data!G11,Data!J11,Data!M11,Data!P11,Data!S11),"",IF(Data!$C11="Lower is better",100*(MAX(Data!D11,Data!G11,Data!J11,Data!M11,Data!P11,Data!S11)-Data!S11)/(MAX(Data!D11,Data!G11,Data!J11,Data!M11,Data!P11,Data!S11)-MIN(Data!D11,Data!G11,Data!J11,Data!M11,Data!P11,Data!S11)),100*(Data!S11-MIN(Data!D11,Data!G11,Data!J11,Data!M11,Data!P11,Data!S11))/(MAX(Data!D11,Data!G11,Data!J11,Data!M11,Data!P11,Data!S11)-MIN(Data!D11,Data!G11,Data!J11,Data!M11,Data!P11,Data!S11)))))
A11: =Indicators!A11 | B11: =Indicators!C11 | C11: =IF(COUNT(Data!D12,Data!G12,Data!J12,Data!M12,Data!P12,Data!S12)<6,"",IF(MAX(Data!D12,Data!G12,Data!J12,Data!M12,Data!P12,Data!S12)=MIN(Data!D12,Data!G12,Data!J12,Data!M12,Data!P12,Data!S12),"",IF(Data!$C12="Lower is better",100*(MAX(Data!D12,Data!G12,Data!J12,Data!M12,Data!P12,Data!S12)-Data!D12)/(MAX(Data!D12,Data!G12,Data!J12,Data!M12,Data!P12,Data!S12)-MIN(Data!D12,Data!G12,Data!J12,Data!M12,Data!P12,Data!S12)),100*(Data!D12-MIN(Data!D12,Data!G12,Data!J12,Data!M12,Data!P12,Data!S12))/(MAX(Data!D12,Data!G12,Data!J12,Data!M12,Data!P12,Data!S12)-MIN(Data!D12,Data!G12,Data!J12,Data!M12,Data!P12,Data!S12))))) | D11: =IF(COUNT(Data!D12,Data!G12,Data!J12,Data!M12,Data!P12,Data!S12)<6,"",IF(MAX(Data!D12,Data!G12,Data!J12,Data!M12,Data!P12,Data!S12)=MIN(Data!D12,Data!G12,Data!J12,Data!M12,Data!P12,Data!S12),"",IF(Data!$C12="Lower is better",100*(MAX(Data!D12,Data!G12,Data!J12,Data!M12,Data!P12,Data!S12)-Data!G12)/(MAX(Data!D12,Data!G12,Data!J12,Data!M12,Data!P12,Data!S12)-MIN(Data!D12,Data!G12,Data!J12,Data!M12,Data!P12,Data!S12)),100*(Data!G12-MIN(Data!D12,Data!G12,Data!J12,Data!M12,Data!P12,Data!S12))/(MAX(Data!D12,Data!G12,Data!J12,Data!M12,Data!P12,Data!S12)-MIN(Data!D12,Data!G12,Data!J12,Data!M12,Data!P12,Data!S12))))) | E11: =IF(COUNT(Data!D12,Data!G12,Data!J12,Data!M12,Data!P12,Data!S12)<6,"",IF(MAX(Data!D12,Data!G12,Data!J12,Data!M12,Data!P12,Data!S12)=MIN(Data!D12,Data!G12,Data!J12,Data!M12,Data!P12,Data!S12),"",IF(Data!$C12="Lower is better",100*(MAX(Data!D12,Data!G12,Data!J12,Data!M12,Data!P12,Data!S12)-Data!J12)/(MAX(Data!D12,Data!G12,Data!J12,Data!M12,Data!P12,Data!S12)-MIN(Data!D12,Data!G12,Data!J12,Data!M12,Data!P12,Data!S12)),100*(Data!J12-MIN(Data!D12,Data!G12,Data!J12,Data!M12,Data!P12,Data!S12))/(MAX(Data!D12,Data!G12,Data!J12,Data!M12,Data!P12,Data!S12)-MIN(Data!D12,Data!G12,Data!J12,Data!M12,Data!P12,Data!S12))))) | F11: =IF(COUNT(Data!D12,Data!G12,Data!J12,Data!M12,Data!P12,Data!S12)<6,"",IF(MAX(Data!D12,Data!G12,Data!J12,Data!M12,Data!P12,Data!S12)=MIN(Data!D12,Data!G12,Data!J12,Data!M12,Data!P12,Data!S12),"",IF(Data!$C12="Lower is better",100*(MAX(Data!D12,Data!G12,Data!J12,Data!M12,Data!P12,Data!S12)-Data!M12)/(MAX(Data!D12,Data!G12,Data!J12,Data!M12,Data!P12,Data!S12)-MIN(Data!D12,Data!G12,Data!J12,Data!M12,Data!P12,Data!S12)),100*(Data!M12-MIN(Data!D12,Data!G12,Data!J12,Data!M12,Data!P12,Data!S12))/(MAX(Data!D12,Data!G12,Data!J12,Data!M12,Data!P12,Data!S12)-MIN(Data!D12,Data!G12,Data!J12,Data!M12,Data!P12,Data!S12))))) | G11: =IF(COUNT(Data!D12,Data!G12,Data!J12,Data!M12,Data!P12,Data!S12)<6,"",IF(MAX(Data!D12,Data!G12,Data!J12,Data!M12,Data!P12,Data!S12)=MIN(Data!D12,Data!G12,Data!J12,Data!M12,Data!P12,Data!S12),"",IF(Data!$C12="Lower is better",100*(MAX(Data!D12,Data!G12,Data!J12,Data!M12,Data!P12,Data!S12)-Data!P12)/(MAX(Data!D12,Data!G12,Data!J12,Data!M12,Data!P12,Data!S12)-MIN(Data!D12,Data!G12,Data!J12,Data!M12,Data!P12,Data!S12)),100*(Data!P12-MIN(Data!D12,Data!G12,Data!J12,Data!M12,Data!P12,Data!S12))/(MAX(Data!D12,Data!G12,Data!J12,Data!M12,Data!P12,Data!S12)-MIN(Data!D12,Data!G12,Data!J12,Data!M12,Data!P12,Data!S12))))) | H11: =IF(COUNT(Data!D12,Data!G12,Data!J12,Data!M12,Data!P12,Data!S12)<6,"",IF(MAX(Data!D12,Data!G12,Data!J12,Data!M12,Data!P12,Data!S12)=MIN(Data!D12,Data!G12,Data!J12,Data!M12,Data!P12,Data!S12),"",IF(Data!$C12="Lower is better",100*(MAX(Data!D12,Data!G12,Data!J12,Data!M12,Data!P12,Data!S12)-Data!S12)/(MAX(Data!D12,Data!G12,Data!J12,Data!M12,Data!P12,Data!S12)-MIN(Data!D12,Data!G12,Data!J12,Data!M12,Data!P12,Data!S12)),100*(Data!S12-MIN(Data!D12,Data!G12,Data!J12,Data!M12,Data!P12,Data!S12))/(MAX(Data!D12,Data!G12,Data!J12,Data!M12,Data!P12,Data!S12)-MIN(Data!D12,Data!G12,Data!J12,Data!M12,Data!P12,Data!S12)))))
A12: =Indicators!A12 | B12: =Indicators!C12 | C12: =IF(COUNT(Data!D13,Data!G13,Data!J13,Data!M13,Data!P13,Data!S13)<6,"",IF(MAX(Data!D13,Data!G13,Data!J13,Data!M13,Data!P13,Data!S13)=MIN(Data!D13,Data!G13,Data!J13,Data!M13,Data!P13,Data!S13),"",IF(Data!$C13="Lower is better",100*(MAX(Data!D13,Data!G13,Data!J13,Data!M13,Data!P13,Data!S13)-Data!D13)/(MAX(Data!D13,Data!G13,Data!J13,Data!M13,Data!P13,Data!S13)-MIN(Data!D13,Data!G13,Data!J13,Data!M13,Data!P13,Data!S13)),100*(Data!D13-MIN(Data!D13,Data!G13,Data!J13,Data!M13,Data!P13,Data!S13))/(MAX(Data!D13,Data!G13,Data!J13,Data!M13,Data!P13,Data!S13)-MIN(Data!D13,Data!G13,Data!J13,Data!M13,Data!P13,Data!S13))))) | D12: =IF(COUNT(Data!D13,Data!G13,Data!J13,Data!M13,Data!P13,Data!S13)<6,"",IF(MAX(Data!D13,Data!G13,Data!J13,Data!M13,Data!P13,Data!S13)=MIN(Data!D13,Data!G13,Data!J13,Data!M13,Data!P13,Data!S13),"",IF(Data!$C13="Lower is better",100*(MAX(Data!D13,Data!G13,Data!J13,Data!M13,Data!P13,Data!S13)-Data!G13)/(MAX(Data!D13,Data!G13,Data!J13,Data!M13,Data!P13,Data!S13)-MIN(Data!D13,Data!G13,Data!J13,Data!M13,Data!P13,Data!S13)),100*(Data!G13-MIN(Data!D13,Data!G13,Data!J13,Data!M13,Data!P13,Data!S13))/(MAX(Data!D13,Data!G13,Data!J13,Data!M13,Data!P13,Data!S13)-MIN(Data!D13,Data!G13,Data!J13,Data!M13,Data!P13,Data!S13))))) | E12: =IF(COUNT(Data!D13,Data!G13,Data!J13,Data!M13,Data!P13,Data!S13)<6,"",IF(MAX(Data!D13,Data!G13,Data!J13,Data!M13,Data!P13,Data!S13)=MIN(Data!D13,Data!G13,Data!J13,Data!M13,Data!P13,Data!S13),"",IF(Data!$C13="Lower is better",100*(MAX(Data!D13,Data!G13,Data!J13,Data!M13,Data!P13,Data!S13)-Data!J13)/(MAX(Data!D13,Data!G13,Data!J13,Data!M13,Data!P13,Data!S13)-MIN(Data!D13,Data!G13,Data!J13,Data!M13,Data!P13,Data!S13)),100*(Data!J13-MIN(Data!D13,Data!G13,Data!J13,Data!M13,Data!P13,Data!S13))/(MAX(Data!D13,Data!G13,Data!J13,Data!M13,Data!P13,Data!S13)-MIN(Data!D13,Data!G13,Data!J13,Data!M13,Data!P13,Data!S13))))) | F12: =IF(COUNT(Data!D13,Data!G13,Data!J13,Data!M13,Data!P13,Data!S13)<6,"",IF(MAX(Data!D13,Data!G13,Data!J13,Data!M13,Data!P13,Data!S13)=MIN(Data!D13,Data!G13,Data!J13,Data!M13,Data!P13,Data!S13),"",IF(Data!$C13="Lower is better",100*(MAX(Data!D13,Data!G13,Data!J13,Data!M13,Data!P13,Data!S13)-Data!M13)/(MAX(Data!D13,Data!G13,Data!J13,Data!M13,Data!P13,Data!S13)-MIN(Data!D13,Data!G13,Data!J13,Data!M13,Data!P13,Data!S13)),100*(Data!M13-MIN(Data!D13,Data!G13,Data!J13,Data!M13,Data!P13,Data!S13))/(MAX(Data!D13,Data!G13,Data!J13,Data!M13,Data!P13,Data!S13)-MIN(Data!D13,Data!G13,Data!J13,Data!M13,Data!P13,Data!S13))))) | G12: =IF(COUNT(Data!D13,Data!G13,Data!J13,Data!M13,Data!P13,Data!S13)<6,"",IF(MAX(Data!D13,Data!G13,Data!J13,Data!M13,Data!P13,Data!S13)=MIN(Data!D13,Data!G13,Data!J13,Data!M13,Data!P13,Data!S13),"",IF(Data!$C13="Lower is better",100*(MAX(Data!D13,Data!G13,Data!J13,Data!M13,Data!P13,Data!S13)-Data!P13)/(MAX(Data!D13,Data!G13,Data!J13,Data!M13,Data!P13,Data!S13)-MIN(Data!D13,Data!G13,Data!J13,Data!M13,Data!P13,Data!S13)),100*(Data!P13-MIN(Data!D13,Data!G13,Data!J13,Data!M13,Data!P13,Data!S13))/(MAX(Data!D13,Data!G13,Data!J13,Data!M13,Data!P13,Data!S13)-MIN(Data!D13,Data!G13,Data!J13,Data!M13,Data!P13,Data!S13))))) | H12: =IF(COUNT(Data!D13,Data!G13,Data!J13,Data!M13,Data!P13,Data!S13)<6,"",IF(MAX(Data!D13,Data!G13,Data!J13,Data!M13,Data!P13,Data!S13)=MIN(Data!D13,Data!G13,Data!J13,Data!M13,Data!P13,Data!S13),"",IF(Data!$C13="Lower is better",100*(MAX(Data!D13,Data!G13,Data!J13,Data!M13,Data!P13,Data!S13)-Data!S13)/(MAX(Data!D13,Data!G13,Data!J13,Data!M13,Data!P13,Data!S13)-MIN(Data!D13,Data!G13,Data!J13,Data!M13,Data!P13,Data!S13)),100*(Data!S13-MIN(Data!D13,Data!G13,Data!J13,Data!M13,Data!P13,Data!S13))/(MAX(Data!D13,Data!G13,Data!J13,Data!M13,Data!P13,Data!S13)-MIN(Data!D13,Data!G13,Data!J13,Data!M13,Data!P13,Data!S13)))))
A13: =Indicators!A13 | B13: =Indicators!C13 | C13: =IF(COUNT(Data!D14,Data!G14,Data!J14,Data!M14,Data!P14,Data!S14)<6,"",IF(MAX(Data!D14,Data!G14,Data!J14,Data!M14,Data!P14,Data!S14)=MIN(Data!D14,Data!G14,Data!J14,Data!M14,Data!P14,Data!S14),"",IF(Data!$C14="Lower is better",100*(MAX(Data!D14,Data!G14,Data!J14,Data!M14,Data!P14,Data!S14)-Data!D14)/(MAX(Data!D14,Data!G14,Data!J14,Data!M14,Data!P14,Data!S14)-MIN(Data!D14,Data!G14,Data!J14,Data!M14,Data!P14,Data!S14)),100*(Data!D14-MIN(Data!D14,Data!G14,Data!J14,Data!M14,Data!P14,Data!S14))/(MAX(Data!D14,Data!G14,Data!J14,Data!M14,Data!P14,Data!S14)-MIN(Data!D14,Data!G14,Data!J14,Data!M14,Data!P14,Data!S14))))) | D13: =IF(COUNT(Data!D14,Data!G14,Data!J14,Data!M14,Data!P14,Data!S14)<6,"",IF(MAX(Data!D14,Data!G14,Data!J14,Data!M14,Data!P14,Data!S14)=MIN(Data!D14,Data!G14,Data!J14,Data!M14,Data!P14,Data!S14),"",IF(Data!$C14="Lower is better",100*(MAX(Data!D14,Data!G14,Data!J14,Data!M14,Data!P14,Data!S14)-Data!G14)/(MAX(Data!D14,Data!G14,Data!J14,Data!M14,Data!P14,Data!S14)-MIN(Data!D14,Data!G14,Data!J14,Data!M14,Data!P14,Data!S14)),100*(Data!G14-MIN(Data!D14,Data!G14,Data!J14,Data!M14,Data!P14,Data!S14))/(MAX(Data!D14,Data!G14,Data!J14,Data!M14,Data!P14,Data!S14)-MIN(Data!D14,Data!G14,Data!J14,Data!M14,Data!P14,Data!S14))))) | E13: =IF(COUNT(Data!D14,Data!G14,Data!J14,Data!M14,Data!P14,Data!S14)<6,"",IF(MAX(Data!D14,Data!G14,Data!J14,Data!M14,Data!P14,Data!S14)=MIN(Data!D14,Data!G14,Data!J14,Data!M14,Data!P14,Data!S14),"",IF(Data!$C14="Lower is better",100*(MAX(Data!D14,Data!G14,Data!J14,Data!M14,Data!P14,Data!S14)-Data!J14)/(MAX(Data!D14,Data!G14,Data!J14,Data!M14,Data!P14,Data!S14)-MIN(Data!D14,Data!G14,Data!J14,Data!M14,Data!P14,Data!S14)),100*(Data!J14-MIN(Data!D14,Data!G14,Data!J14,Data!M14,Data!P14,Data!S14))/(MAX(Data!D14,Data!G14,Data!J14,Data!M14,Data!P14,Data!S14)-MIN(Data!D14,Data!G14,Data!J14,Data!M14,Data!P14,Data!S14))))) | F13: =IF(COUNT(Data!D14,Data!G14,Data!J14,Data!M14,Data!P14,Data!S14)<6,"",IF(MAX(Data!D14,Data!G14,Data!J14,Data!M14,Data!P14,Data!S14)=MIN(Data!D14,Data!G14,Data!J14,Data!M14,Data!P14,Data!S14),"",IF(Data!$C14="Lower is better",100*(MAX(Data!D14,Data!G14,Data!J14,Data!M14,Data!P14,Data!S14)-Data!M14)/(MAX(Data!D14,Data!G14,Data!J14,Data!M14,Data!P14,Data!S14)-MIN(Data!D14,Data!G14,Data!J14,Data!M14,Data!P14,Data!S14)),100*(Data!M14-MIN(Data!D14,Data!G14,Data!J14,Data!M14,Data!P14,Data!S14))/(MAX(Data!D14,Data!G14,Data!J14,Data!M14,Data!P14,Data!S14)-MIN(Data!D14,Data!G14,Data!J14,Data!M14,Data!P14,Data!S14))))) | G13: =IF(COUNT(Data!D14,Data!G14,Data!J14,Data!M14,Data!P14,Data!S14)<6,"",IF(MAX(Data!D14,Data!G14,Data!J14,Data!M14,Data!P14,Data!S14)=MIN(Data!D14,Data!G14,Data!J14,Data!M14,Data!P14,Data!S14),"",IF(Data!$C14="Lower is better",100*(MAX(Data!D14,Data!G14,Data!J14,Data!M14,Data!P14,Data!S14)-Data!P14)/(MAX(Data!D14,Data!G14,Data!J14,Data!M14,Data!P14,Data!S14)-MIN(Data!D14,Data!G14,Data!J14,Data!M14,Data!P14,Data!S14)),100*(Data!P14-MIN(Data!D14,Data!G14,Data!J14,Data!M14,Data!P14,Data!S14))/(MAX(Data!D14,Data!G14,Data!J14,Data!M14,Data!P14,Data!S14)-MIN(Data!D14,Data!G14,Data!J14,Data!M14,Data!P14,Data!S14))))) | H13: =IF(COUNT(Data!D14,Data!G14,Data!J14,Data!M14,Data!P14,Data!S14)<6,"",IF(MAX(Data!D14,Data!G14,Data!J14,Data!M14,Data!P14,Data!S14)=MIN(Data!D14,Data!G14,Data!J14,Data!M14,Data!P14,Data!S14),"",IF(Data!$C14="Lower is better",100*(MAX(Data!D14,Data!G14,Data!J14,Data!M14,Data!P14,Data!S14)-Data!S14)/(MAX(Data!D14,Data!G14,Data!J14,Data!M14,Data!P14,Data!S14)-MIN(Data!D14,Data!G14,Data!J14,Data!M14,Data!P14,Data!S14)),100*(Data!S14-MIN(Data!D14,Data!G14,Data!J14,Data!M14,Data!P14,Data!S14))/(MAX(Data!D14,Data!G14,Data!J14,Data!M14,Data!P14,Data!S14)-MIN(Data!D14,Data!G14,Data!J14,Data!M14,Data!P14,Data!S14)))))
A14: =Indicators!A14 | B14: =Indicators!C14 | C14: =IF(COUNT(Data!D15,Data!G15,Data!J15,Data!M15,Data!P15,Data!S15)<6,"",IF(MAX(Data!D15,Data!G15,Data!J15,Data!M15,Data!P15,Data!S15)=MIN(Data!D15,Data!G15,Data!J15,Data!M15,Data!P15,Data!S15),"",IF(Data!$C15="Lower is better",100*(MAX(Data!D15,Data!G15,Data!J15,Data!M15,Data!P15,Data!S15)-Data!D15)/(MAX(Data!D15,Data!G15,Data!J15,Data!M15,Data!P15,Data!S15)-MIN(Data!D15,Data!G15,Data!J15,Data!M15,Data!P15,Data!S15)),100*(Data!D15-MIN(Data!D15,Data!G15,Data!J15,Data!M15,Data!P15,Data!S15))/(MAX(Data!D15,Data!G15,Data!J15,Data!M15,Data!P15,Data!S15)-MIN(Data!D15,Data!G15,Data!J15,Data!M15,Data!P15,Data!S15))))) | D14: =IF(COUNT(Data!D15,Data!G15,Data!J15,Data!M15,Data!P15,Data!S15)<6,"",IF(MAX(Data!D15,Data!G15,Data!J15,Data!M15,Data!P15,Data!S15)=MIN(Data!D15,Data!G15,Data!J15,Data!M15,Data!P15,Data!S15),"",IF(Data!$C15="Lower is better",100*(MAX(Data!D15,Data!G15,Data!J15,Data!M15,Data!P15,Data!S15)-Data!G15)/(MAX(Data!D15,Data!G15,Data!J15,Data!M15,Data!P15,Data!S15)-MIN(Data!D15,Data!G15,Data!J15,Data!M15,Data!P15,Data!S15)),100*(Data!G15-MIN(Data!D15,Data!G15,Data!J15,Data!M15,Data!P15,Data!S15))/(MAX(Data!D15,Data!G15,Data!J15,Data!M15,Data!P15,Data!S15)-MIN(Data!D15,Data!G15,Data!J15,Data!M15,Data!P15,Data!S15))))) | E14: =IF(COUNT(Data!D15,Data!G15,Data!J15,Data!M15,Data!P15,Data!S15)<6,"",IF(MAX(Data!D15,Data!G15,Data!J15,Data!M15,Data!P15,Data!S15)=MIN(Data!D15,Data!G15,Data!J15,Data!M15,Data!P15,Data!S15),"",IF(Data!$C15="Lower is better",100*(MAX(Data!D15,Data!G15,Data!J15,Data!M15,Data!P15,Data!S15)-Data!J15)/(MAX(Data!D15,Data!G15,Data!J15,Data!M15,Data!P15,Data!S15)-MIN(Data!D15,Data!G15,Data!J15,Data!M15,Data!P15,Data!S15)),100*(Data!J15-MIN(Data!D15,Data!G15,Data!J15,Data!M15,Data!P15,Data!S15))/(MAX(Data!D15,Data!G15,Data!J15,Data!M15,Data!P15,Data!S15)-MIN(Data!D15,Data!G15,Data!J15,Data!M15,Data!P15,Data!S15))))) | F14: =IF(COUNT(Data!D15,Data!G15,Data!J15,Data!M15,Data!P15,Data!S15)<6,"",IF(MAX(Data!D15,Data!G15,Data!J15,Data!M15,Data!P15,Data!S15)=MIN(Data!D15,Data!G15,Data!J15,Data!M15,Data!P15,Data!S15),"",IF(Data!$C15="Lower is better",100*(MAX(Data!D15,Data!G15,Data!J15,Data!M15,Data!P15,Data!S15)-Data!M15)/(MAX(Data!D15,Data!G15,Data!J15,Data!M15,Data!P15,Data!S15)-MIN(Data!D15,Data!G15,Data!J15,Data!M15,Data!P15,Data!S15)),100*(Data!M15-MIN(Data!D15,Data!G15,Data!J15,Data!M15,Data!P15,Data!S15))/(MAX(Data!D15,Data!G15,Data!J15,Data!M15,Data!P15,Data!S15)-MIN(Data!D15,Data!G15,Data!J15,Data!M15,Data!P15,Data!S15))))) | G14: =IF(COUNT(Data!D15,Data!G15,Data!J15,Data!M15,Data!P15,Data!S15)<6,"",IF(MAX(Data!D15,Data!G15,Data!J15,Data!M15,Data!P15,Data!S15)=MIN(Data!D15,Data!G15,Data!J15,Data!M15,Data!P15,Data!S15),"",IF(Data!$C15="Lower is better",100*(MAX(Data!D15,Data!G15,Data!J15,Data!M15,Data!P15,Data!S15)-Data!P15)/(MAX(Data!D15,Data!G15,Data!J15,Data!M15,Data!P15,Data!S15)-MIN(Data!D15,Data!G15,Data!J15,Data!M15,Data!P15,Data!S15)),100*(Data!P15-MIN(Data!D15,Data!G15,Data!J15,Data!M15,Data!P15,Data!S15))/(MAX(Data!D15,Data!G15,Data!J15,Data!M15,Data!P15,Data!S15)-MIN(Data!D15,Data!G15,Data!J15,Data!M15,Data!P15,Data!S15))))) | H14: =IF(COUNT(Data!D15,Data!G15,Data!J15,Data!M15,Data!P15,Data!S15)<6,"",IF(MAX(Data!D15,Data!G15,Data!J15,Data!M15,Data!P15,Data!S15)=MIN(Data!D15,Data!G15,Data!J15,Data!M15,Data!P15,Data!S15),"",IF(Data!$C15="Lower is better",100*(MAX(Data!D15,Data!G15,Data!J15,Data!M15,Data!P15,Data!S15)-Data!S15)/(MAX(Data!D15,Data!G15,Data!J15,Data!M15,Data!P15,Data!S15)-MIN(Data!D15,Data!G15,Data!J15,Data!M15,Data!P15,Data!S15)),100*(Data!S15-MIN(Data!D15,Data!G15,Data!J15,Data!M15,Data!P15,Data!S15))/(MAX(Data!D15,Data!G15,Data!J15,Data!M15,Data!P15,Data!S15)-MIN(Data!D15,Data!G15,Data!J15,Data!M15,Data!P15,Data!S15)))))
A15: =Indicators!A15 | B15: =Indicators!C15 | C15: =IF(COUNT(Data!D16,Data!G16,Data!J16,Data!M16,Data!P16,Data!S16)<6,"",IF(MAX(Data!D16,Data!G16,Data!J16,Data!M16,Data!P16,Data!S16)=MIN(Data!D16,Data!G16,Data!J16,Data!M16,Data!P16,Data!S16),"",IF(Data!$C16="Lower is better",100*(MAX(Data!D16,Data!G16,Data!J16,Data!M16,Data!P16,Data!S16)-Data!D16)/(MAX(Data!D16,Data!G16,Data!J16,Data!M16,Data!P16,Data!S16)-MIN(Data!D16,Data!G16,Data!J16,Data!M16,Data!P16,Data!S16)),100*(Data!D16-MIN(Data!D16,Data!G16,Data!J16,Data!M16,Data!P16,Data!S16))/(MAX(Data!D16,Data!G16,Data!J16,Data!M16,Data!P16,Data!S16)-MIN(Data!D16,Data!G16,Data!J16,Data!M16,Data!P16,Data!S16))))) | D15: =IF(COUNT(Data!D16,Data!G16,Data!J16,Data!M16,Data!P16,Data!S16)<6,"",IF(MAX(Data!D16,Data!G16,Data!J16,Data!M16,Data!P16,Data!S16)=MIN(Data!D16,Data!G16,Data!J16,Data!M16,Data!P16,Data!S16),"",IF(Data!$C16="Lower is better",100*(MAX(Data!D16,Data!G16,Data!J16,Data!M16,Data!P16,Data!S16)-Data!G16)/(MAX(Data!D16,Data!G16,Data!J16,Data!M16,Data!P16,Data!S16)-MIN(Data!D16,Data!G16,Data!J16,Data!M16,Data!P16,Data!S16)),100*(Data!G16-MIN(Data!D16,Data!G16,Data!J16,Data!M16,Data!P16,Data!S16))/(MAX(Data!D16,Data!G16,Data!J16,Data!M16,Data!P16,Data!S16)-MIN(Data!D16,Data!G16,Data!J16,Data!M16,Data!P16,Data!S16))))) | E15: =IF(COUNT(Data!D16,Data!G16,Data!J16,Data!M16,Data!P16,Data!S16)<6,"",IF(MAX(Data!D16,Data!G16,Data!J16,Data!M16,Data!P16,Data!S16)=MIN(Data!D16,Data!G16,Data!J16,Data!M16,Data!P16,Data!S16),"",IF(Data!$C16="Lower is better",100*(MAX(Data!D16,Data!G16,Data!J16,Data!M16,Data!P16,Data!S16)-Data!J16)/(MAX(Data!D16,Data!G16,Data!J16,Data!M16,Data!P16,Data!S16)-MIN(Data!D16,Data!G16,Data!J16,Data!M16,Data!P16,Data!S16)),100*(Data!J16-MIN(Data!D16,Data!G16,Data!J16,Data!M16,Data!P16,Data!S16))/(MAX(Data!D16,Data!G16,Data!J16,Data!M16,Data!P16,Data!S16)-MIN(Data!D16,Data!G16,Data!J16,Data!M16,Data!P16,Data!S16))))) | F15: =IF(COUNT(Data!D16,Data!G16,Data!J16,Data!M16,Data!P16,Data!S16)<6,"",IF(MAX(Data!D16,Data!G16,Data!J16,Data!M16,Data!P16,Data!S16)=MIN(Data!D16,Data!G16,Data!J16,Data!M16,Data!P16,Data!S16),"",IF(Data!$C16="Lower is better",100*(MAX(Data!D16,Data!G16,Data!J16,Data!M16,Data!P16,Data!S16)-Data!M16)/(MAX(Data!D16,Data!G16,Data!J16,Data!M16,Data!P16,Data!S16)-MIN(Data!D16,Data!G16,Data!J16,Data!M16,Data!P16,Data!S16)),100*(Data!M16-MIN(Data!D16,Data!G16,Data!J16,Data!M16,Data!P16,Data!S16))/(MAX(Data!D16,Data!G16,Data!J16,Data!M16,Data!P16,Data!S16)-MIN(Data!D16,Data!G16,Data!J16,Data!M16,Data!P16,Data!S16))))) | G15: =IF(COUNT(Data!D16,Data!G16,Data!J16,Data!M16,Data!P16,Data!S16)<6,"",IF(MAX(Data!D16,Data!G16,Data!J16,Data!M16,Data!P16,Data!S16)=MIN(Data!D16,Data!G16,Data!J16,Data!M16,Data!P16,Data!S16),"",IF(Data!$C16="Lower is better",100*(MAX(Data!D16,Data!G16,Data!J16,Data!M16,Data!P16,Data!S16)-Data!P16)/(MAX(Data!D16,Data!G16,Data!J16,Data!M16,Data!P16,Data!S16)-MIN(Data!D16,Data!G16,Data!J16,Data!M16,Data!P16,Data!S16)),100*(Data!P16-MIN(Data!D16,Data!G16,Data!J16,Data!M16,Data!P16,Data!S16))/(MAX(Data!D16,Data!G16,Data!J16,Data!M16,Data!P16,Data!S16)-MIN(Data!D16,Data!G16,Data!J16,Data!M16,Data!P16,Data!S16))))) | H15: =IF(COUNT(Data!D16,Data!G16,Data!J16,Data!M16,Data!P16,Data!S16)<6,"",IF(MAX(Data!D16,Data!G16,Data!J16,Data!M16,Data!P16,Data!S16)=MIN(Data!D16,Data!G16,Data!J16,Data!M16,Data!P16,Data!S16),"",IF(Data!$C16="Lower is better",100*(MAX(Data!D16,Data!G16,Data!J16,Data!M16,Data!P16,Data!S16)-Data!S16)/(MAX(Data!D16,Data!G16,Data!J16,Data!M16,Data!P16,Data!S16)-MIN(Data!D16,Data!G16,Data!J16,Data!M16,Data!P16,Data!S16)),100*(Data!S16-MIN(Data!D16,Data!G16,Data!J16,Data!M16,Data!P16,Data!S16))/(MAX(Data!D16,Data!G16,Data!J16,Data!M16,Data!P16,Data!S16)-MIN(Data!D16,Data!G16,Data!J16,Data!M16,Data!P16,Data!S16)))))
