Workbook

Sheet Instructions
A1: PESTEL indicator search: Julius Meinl in Latin America
A2: Business Projects WT 2026/27, midterm presentation (country selection). Countries: Argentina, Brazil, Chile, Colombia, Mexico, Uruguay.
A4: Purpose | B4: Collect indicators that could describe the six countries for a premium coffee launch by Julius Meinl. Search for indicators for each PESTEL dimension first (political, economic, social, technological, environmental, legal). In the next step you shortlist 8 to 14 of them for your scoring model.
A6: What to do | B6: 1. Make your own copy: File > Make a copy. Name it "Group X: PESTEL indicators". Share it with your team members (Editor) and with the instructor (Editor): arne.floh@wu.ac.at.
B7: 2. Read the tab "PESTEL guide" to see what each dimension covers and which question it answers for Julius Meinl.
B8: 3. In the tab "Long list", find at least as many candidate indicators per dimension as the Summary tab asks for. The rows marked "Instructor" are starting points; add your own rows below them and mark them "Group".
B9: 4. For every indicator, fill in the definition, source, link and direction. Open the source and check whether data exist for each of the six countries. Set each country to Yes, Partly, No or Not checked. The instructor has not checked coverage: this is your first task.
B10: 5. Rate each indicator for relevance and data quality (1 to 5).
B11: 6. Mark 8 to 14 indicators as Shortlist = Yes. Use the Summary tab to check that every dimension and all six Julius Meinl dimensions are represented and that the shortlisted indicators cover all six countries.
B12: 7. Copy the shortlist into the Criteria sheet of your Excel model.
A14: Rules | B14: The source link opens the page where the data can be downloaded, not the home page of the publisher.
B15: Write the latest year as text, for example 2024. Check the latest edition before you rely on a number.
B16: Do not delete the instructor's rows. If you do not use an indicator, leave Shortlist empty and say why in the comment.
B17: AI tools may help you to find indicators. Open the source yourself and confirm the data exist for all six countries before you enter Yes. List the tools you used in the comment of the row.
B18: Qualitative indicators need a rubric: write the meaning of each score from 1 to 5 in the comment.
A20: Colour code | B20: Blue text: typed by you or by the instructor (inputs).
B21: Black text on grey: formula, do not edit.
B22: Yellow fill: still to be confirmed by the instructor.
A24: Deadline for the long list | B24: [date, to be confirmed]
A27: How to fill in a row (example)
A28: Column in "Long list" | B28: Example entry
A29: PESTEL dimension | B29: Economic
A30: Indicator | B30: GDP per capita, PPP
A31: What it measures | B31: Output per person, adjusted for differences in price levels
A32: Julius Meinl dimension | B32: Purchasing power
A33: Type | B33: Quantitative
A34: Unit | B34: International dollars, current
A35: Direction | B35: Higher is better
A36: Source name | B36: World Development Indicators, World Bank
A37: Source link | B37: https://databank.worldbank.org/source/world-development-indicators
A38: Latest year | B38: 2024
A39: Argentina to Uruguay | B39: Yes (six columns, one per country)
... A44: Comment | B44: Use PPP rather than current US dollars to compare spending power.

Sheet PESTEL guide
A1: Dimension | B1: What it covers for a premium coffee launch | C1: Question to answer for Julius Meinl | D1: Related Julius Meinl dimensions | E1: Ideas to search for
A2: Political | B2: Stability, governance quality, and the government's stance on trade and foreign business. | C2: Can a foreign premium brand and its local partner operate here without political or institutional surprises? | D2: Import and regulation | E2: Political stability, government effectiveness, corruption perception, economic freedom, trade agreement with the EU, country risk rating.
A3: Economic | B3: Size, growth and spending power of the economy, tourism income, trade conditions and costs. | C3: Is there enough premium demand, and can Julius Meinl reach it at a viable cost? | D3: Premium coffee segment; Purchasing power; Tourism and hotels; Import and regulation | E3: GDP per capita (PPP), growth, household consumption, inflation and exchange rate, tourism receipts, coffee imports, tariffs on roasted coffee.
A4: Social | B4: Demographics, lifestyle, culture and consumption habits, visitors. | C4: Do consumers and hotel guests value what Julius Meinl sells: Viennese coffee house culture, service and time for a cup of coffee? | D4: Coffee culture; Tourism and hotels | E4: Coffee consumption per capita, urbanisation, cultural distance from Austria, visitors from Europe, café culture, European influence.
A5: Technological | B5: Digital and logistics infrastructure, and how people shop and pay. | C5: Can Julius Meinl reach customers through modern channels with reliable logistics? | D5: Premium coffee segment; Import and regulation | E5: Internet use, online retail and food delivery, digital payments, logistics performance, innovation capability.
A6: Environmental | B6: Climate, sustainability expectations and supply risks. | C6: Do sustainability expectations or climate risks change demand, supply or the fit of the brand? | D6: Coffee culture; Competitive landscape | E6: Climate vulnerability, environmental performance, demand for certified coffee, domestic coffee production.
A7: Legal | B7: Rules for importing, selling and doing business, and how reliably they are enforced. | C7: What must Julius Meinl comply with, and can contracts with a local partner be enforced? | D7: Import and regulation | E7: Regulatory quality, rule of law, product and labelling requirements, trademark protection, rules on ending distribution agreements, ease of doing business.

Sheet Long list
A1: ID | B1: PESTEL dimension | C1: Indicator | D1: What it measures | E1: Julius Meinl dimension | F1: Type | G1: Unit | H1: Direction | I1: Source name | J1: Source link | K1: Latest year | L1: Argentina | M1: Brazil | N1: Chile | O1: Colombia | P1: Mexico | Q1: Uruguay | R1: Countries covered | S1: Relevance (1-5) | T1: Data quality (1-5) | U1: Shortlist? | V1: Shortlist check | W1: Suggested by | X1: Found by | Y1: Date checked | Z1: Comment
A2: =IF(B2="","",UPPER(LEFT(B2,2))&TEXT(COUNTIF(B$2:B2,B2),"00")) | B2: Political | C2: Political stability and absence of violence | D2: Likelihood of political instability or politically motivated violence | E2: Other (explain) | F2: Quantitative | G2: Estimate, about -2.5 to 2.5 | H2: Higher is better | I2: Worldwide Governance Indicators, World Bank | J2: https://www.worldbank.org/en/publication/worldwide-governance-indicators | L2: Not checked | M2: Not checked | N2: Not checked | O2: Not checked | P2: Not checked | Q2: Not checked | R2: =IF(C2="","",COUNTIF(L2:Q2,"Yes")) | V2: =IF(U2="Yes",IF(R2=6,"OK","Coverage gap"),"") | W2: Instructor | Z2: Country risk is not one of Julius Meinl's six dimensions; explain why you include it.
A3: =IF(B3="","",UPPER(LEFT(B3,2))&TEXT(COUNTIF(B$2:B3,B3),"00")) | B3: Political | C3: Government effectiveness | D3: Quality of public services and of policy implementation | E3: Other (explain) | F3: Quantitative | G3: Estimate, about -2.5 to 2.5 | H3: Higher is better | I3: Worldwide Governance Indicators, World Bank | J3: https://www.worldbank.org/en/publication/worldwide-governance-indicators | L3: Not checked | M3: Not checked | N3: Not checked | O3: Not checked | P3: Not checked | Q3: Not checked | R3: =IF(C3="","",COUNTIF(L3:Q3,"Yes")) | V3: =IF(U3="Yes",IF(R3=6,"OK","Coverage gap"),"") | W3: Instructor
A4: =IF(B4="","",UPPER(LEFT(B4,2))&TEXT(COUNTIF(B$2:B4,B4),"00")) | B4: Political | C4: Corruption Perceptions Index | D4: Perceived corruption in the public sector | E4: Other (explain) | F4: Quantitative | G4: Score 0 (highly corrupt) to 100 (very clean) | H4: Higher is better | I4: Transparency International | J4: https://www.transparency.org/en/cpi/2025 | L4: Not checked | M4: Not checked | N4: Not checked | O4: Not checked | P4: Not checked | Q4: Not checked | R4: =IF(C4="","",COUNTIF(L4:Q4,"Yes")) | V4: =IF(U4="Yes",IF(R4=6,"OK","Coverage gap"),"") | W4: Instructor | Z4: Link shows one edition; use the latest.
A5: =IF(B5="","",UPPER(LEFT(B5,2))&TEXT(COUNTIF(B$2:B5,B5),"00")) | B5: Political | C5: Index of Economic Freedom, overall score | D5: Economic freedom in 12 areas, such as property rights and trade freedom | E5: Import and regulation | F5: Quantitative | G5: Score 0 to 100 | H5: Higher is better | I5: The Heritage Foundation | J5: https://www.heritage.org/index/ | L5: Not checked | M5: Not checked | N5: Not checked | O5: Not checked | P5: Not checked | Q5: Not checked | R5: =IF(C5="","",COUNTIF(L5:Q5,"Yes")) | V5: =IF(U5="Yes",IF(R5=6,"OK","Coverage gap"),"") | W5: Instructor
A6: =IF(B6="","",UPPER(LEFT(B6,2))&TEXT(COUNTIF(B$2:B6,B6),"00")) | B6: Political | C6: Trade agreement between the EU and the country | D6: Whether an agreement applies and what it means for duties and access | E6: Import and regulation | F6: Qualitative rubric | G6: Score 1 to 5 | H6: Higher is better | I6: EU Access2Markets | J6: https://trade.ec.europa.eu/access-to-markets/en/content/what-access2markets-0 | L6: Not checked | M6: Not checked | N6: Not checked | O6: Not checked | P6: Not checked | Q6: Not checked | R6: =IF(C6="","",COUNTIF(L6:Q6,"Yes")) | V6: =IF(U6="Yes",IF(R6=6,"OK","Coverage gap"),"") | W6: Instructor | Z6: Look up the current status and record the date.
A7: =IF(B7="","",UPPER(LEFT(B7,2))&TEXT(COUNTIF(B$2:B7,B7),"00")) | B7: Political | C7: Country risk rating | D7: Insurer's rating of the average probability of payment default | E7: Other (explain) | F7: Qualitative rubric | G7: Rating A1 to E | H7: Higher is better | I7: Coface country risk assessments | J7: https://www.coface.com/news-economy-and-insights/business-risk-dashboard/country-risk-files | L7: Not checked | M7: Not checked | N7: Not checked | O7: Not checked | P7: Not checked | Q7: Not checked | R7: =IF(C7="","",COUNTIF(L7:Q7,"Yes")) | V7: =IF(U7="Yes",IF(R7=6,"OK","Coverage gap"),"") | W7: Instructor | Z7: Convert the rating to numbers and say how.
A8: =IF(B8="","",UPPER(LEFT(B8,2))&TEXT(COUNTIF(B$2:B8,B8),"00")) | B8: Economic | C8: GDP per capita, PPP | D8: Output per person, adjusted for differences in price levels | E8: Purchasing power | F8: Quantitative | G8: International dollars, current | H8: Higher is better | I8: World Development Indicators, World Bank | J8: https://databank.worldbank.org/source/world-development-indicators | L8: Not checked | M8: Not checked | N8: Not checked | O8: Not checked | P8: Not checked | Q8: Not checked | R8: =IF(C8="","",COUNTIF(L8:Q8,"Yes")) | V8: =IF(U8="Yes",IF(R8=6,"OK","Coverage gap"),"") | W8: Instructor
A9: =IF(B9="","",UPPER(LEFT(B9,2))&TEXT(COUNTIF(B$2:B9,B9),"00")) | B9: Economic | C9: GDP growth, projected | D9: Expected real growth of the economy over the next years | E9: Other (explain) | F9: Quantitative | G9: % per year | H9: Higher is better | I9: World Economic Outlook, IMF | J9: https://data.imf.org/datasets/WEO | L9: Not checked | M9: Not checked | N9: Not checked | O9: Not checked | P9: Not checked | Q9: Not checked | R9: =IF(C9="","",COUNTIF(L9:Q9,"Yes")) | V9: =IF(U9="Yes",IF(R9=6,"OK","Coverage gap"),"") | W9: Instructor | Z9: Compare projections with past growth.
A10: =IF(B10="","",UPPER(LEFT(B10,2))&TEXT(COUNTIF(B$2:B10,B10),"00")) | B10: Economic | C10: Household final consumption expenditure per capita | D10: Average household spending per person | E10: Premium coffee segment | F10: Quantitative | G10: US dollars | H10: Higher is better | I10: World Development Indicators, World Bank | J10: https://databank.worldbank.org/source/world-development-indicators | L10: Not checked | M10: Not checked | N10: Not checked | O10: Not checked | P10: Not checked | Q10: Not checked | R10: =IF(C10="","",COUNTIF(L10:Q10,"Yes")) | V10: =IF(U10="Yes",IF(R10=6,"OK","Coverage gap"),"") | W10: Instructor
A11: =IF(B11="","",UPPER(LEFT(B11,2))&TEXT(COUNTIF(B$2:B11,B11),"00")) | B11: Economic | C11: Inflation, consumer prices | D11: Annual change in consumer prices | E11: Purchasing power | F11: Quantitative | G11: % per year | H11: Lower is better | I11: World Development Indicators, World Bank | J11: https://databank.worldbank.org/source/world-development-indicators | L11: Not checked | M11: Not checked | N11: Not checked | O11: Not checked | P11: Not checked | Q11: Not checked | R11: =IF(C11="","",COUNTIF(L11:Q11,"Yes")) | V11: =IF(U11="Yes",IF(R11=6,"OK","Coverage gap"),"") | W11: Instructor | Z11: The IMF World Economic Outlook also has projections.
A12: =IF(B12="","",UPPER(LEFT(B12,2))&TEXT(COUNTIF(B$2:B12,B12),"00")) | B12: Economic | C12: International tourism, receipts | D12: Spending by international visitors in the country | E12: Tourism and hotels | F12: Quantitative | G12: US dollars | H12: Higher is better | I12: World Development Indicators, World Bank | J12: https://databank.worldbank.org/source/world-development-indicators | L12: Not checked | M12: Not checked | N12: Not checked | O12: Not checked | P12: Not checked | Q12: Not checked | R12: =IF(C12="","",COUNTIF(L12:Q12,"Yes")) | V12: =IF(U12="Yes",IF(R12=6,"OK","Coverage gap"),"") | W12: Instructor
A13: =IF(B13="","",UPPER(LEFT(B13,2))&TEXT(COUNTIF(B$2:B13,B13),"00")) | B13: Economic | C13: Coffee imports (HS 0901), value and growth | D13: Value of coffee imports and how fast they grow | E13: Premium coffee segment | F13: Quantitative | G13: US dollars; % per year | H13: Higher is better | I13: ITC Trade Map | J13: https://www.trademap.org/ | L13: Not checked | M13: Not checked | N13: Not checked | O13: Not checked | P13: Not checked | Q13: Not checked | R13: =IF(C13="","",COUNTIF(L13:Q13,"Yes")) | V13: =IF(U13="Yes",IF(R13=6,"OK","Coverage gap"),"") | W13: Instructor | Z13: Check whether imports are large enough to be meaningful in coffee-producing countries.
A14: =IF(B14="","",UPPER(LEFT(B14,2))&TEXT(COUNTIF(B$2:B14,B14),"00")) | B14: Economic | C14: Applied tariff on roasted coffee (HS 0901.21), EU origin | D14: Duty that Julius Meinl would pay at the border | E14: Import and regulation | F14: Quantitative | G14: % | H14: Lower is better | I14: EU Access2Markets; WTO tariff data | J14: https://trade.ec.europa.eu/access-to-markets/en/content/what-access2markets-0 | L14: Not checked | M14: Not checked | N14: Not checked | O14: Not checked | P14: Not checked | Q14: Not checked | R14: =IF(C14="","",COUNTIF(L14:Q14,"Yes")) | V14: =IF(U14="Yes",IF(R14=6,"OK","Coverage gap"),"") | W14: Instructor
A15: =IF(B15="","",UPPER(LEFT(B15,2))&TEXT(COUNTIF(B$2:B15,B15),"00")) | B15: Social | C15: Coffee consumption per capita | D15: Domestic coffee consumption per person | E15: Coffee culture | F15: Quantitative | G15: Kilograms per person (check the unit in the source) | H15: Higher is better | I15: International Coffee Organization | J15: https://www.ico.org/ | L15: Not checked | M15: Not checked | N15: Not checked | O15: Not checked | P15: Not checked | Q15: Not checked | R15: =IF(C15="","",COUNTIF(L15:Q15,"Yes")) | V15: =IF(U15="Yes",IF(R15=6,"OK","Coverage gap"),"") | W15: Instructor | Z15: Not in the World Bank data; search the ICO statistics.
A16: =IF(B16="","",UPPER(LEFT(B16,2))&TEXT(COUNTIF(B$2:B16,B16),"00")) | B16: Social | C16: Urban population share | D16: Share of the population that lives in cities | E16: Premium coffee segment | F16: Quantitative | G16: % of population | H16: Higher is better | I16: World Development Indicators, World Bank | J16: https://databank.worldbank.org/source/world-development-indicators | L16: Not checked | M16: Not checked | N16: Not checked | O16: Not checked | P16: Not checked | Q16: Not checked | R16: =IF(C16="","",COUNTIF(L16:Q16,"Yes")) | V16: =IF(U16="Yes",IF(R16=6,"OK","Coverage gap"),"") | W16: Instructor
A17: =IF(B17="","",UPPER(LEFT(B17,2))&TEXT(COUNTIF(B$2:B17,B17),"00")) | B17: Social | C17: Cultural distance from Austria | D17: Distance on Hofstede's six dimensions, for example as a Kogut-Singh index | E17: Other (explain) | F17: Quantitative | G17: Index, calculated by you | H17: Lower is better | I17: Hofstede dimension data matrix | J17: https://geerthofstede.com/research-and-vsm/dimension-data-matrix/ | L17: Not checked | M17: Not checked | N17: Not checked | O17: Not checked | P17: Not checked | Q17: Not checked | R17: =IF(C17="","",COUNTIF(L17:Q17,"Yes")) | V17: =IF(U17="Yes",IF(R17=6,"OK","Coverage gap"),"") | W17: Instructor | Z17: Calculate it yourselves and note the critique of the Hofstede approach.
A18: =IF(B18="","",UPPER(LEFT(B18,2))&TEXT(COUNTIF(B$2:B18,B18),"00")) | B18: Social | C18: International tourist arrivals | D18: Number of international visitors per year | E18: Tourism and hotels | F18: Quantitative | G18: Number of arrivals | H18: Higher is better | I18: World Development Indicators, World Bank (UN Tourism data) | J18: https://databank.worldbank.org/source/world-development-indicators | L18: Not checked | M18: Not checked | N18: Not checked | O18: Not checked | P18: Not checked | Q18: Not checked | R18: =IF(C18="","",COUNTIF(L18:Q18,"Yes")) | V18: =IF(U18="Yes",IF(R18=6,"OK","Coverage gap"),"") | W18: Instructor
A19: =IF(B19="","",UPPER(LEFT(B19,2))&TEXT(COUNTIF(B$2:B19,B19),"00")) | B19: Social | C19: Share of visitors from Europe | D19: Share of international arrivals that come from Europe | E19: Tourism and hotels | F19: Quantitative | G19: % of arrivals | H19: Higher is better | I19: National tourism statistics | L19: Not checked | M19: Not checked | N19: Not checked | O19: Not checked | P19: Not checked | Q19: Not checked | R19: =IF(C19="","",COUNTIF(L19:Q19,"Yes")) | V19: =IF(U19="Yes",IF(R19=6,"OK","Coverage gap"),"") | W19: Instructor | Z19: Find the national source; it may exist for only some countries.
A20: =IF(B20="","",UPPER(LEFT(B20,2))&TEXT(COUNTIF(B$2:B20,B20),"00")) | B20: Social | C20: Café culture | D20: Importance of cafés and coffee-house tradition in everyday life | E20: Coffee culture | F20: Qualitative rubric | G20: Score 1 to 5 | H20: Higher is better | I20: Own assessment (industry reports, travel guides) | L20: Not checked | M20: Not checked | N20: Not checked | O20: Not checked | P20: Not checked | Q20: Not checked | R20: =IF(C20="","",COUNTIF(L20:Q20,"Yes")) | V20: =IF(U20="Yes",IF(R20=6,"OK","Coverage gap"),"") | W20: Instructor | Z20: Define each score and let two team members rate independently.
A21: =IF(B21="","",UPPER(LEFT(B21,2))&TEXT(COUNTIF(B$2:B21,B21),"00")) | B21: Social | C21: European influence on coffee culture | D21: Presence of a European café tradition, for example through migration history | E21: Coffee culture | F21: Qualitative rubric | G21: Score 1 to 5 | H21: Higher is better | I21: Own assessment (industry reports, history sources) | L21: Not checked | M21: Not checked | N21: Not checked | O21: Not checked | P21: Not checked | Q21: Not checked | R21: =IF(C21="","",COUNTIF(L21:Q21,"Yes")) | V21: =IF(U21="Yes",IF(R21=6,"OK","Coverage gap"),"") | W21: Instructor | Z21: Julius Meinl assumes this matters. The assumption is unverified.
A22: =IF(B22="","",UPPER(LEFT(B22,2))&TEXT(COUNTIF(B$2:B22,B22),"00")) | B22: Technological | C22: Individuals using the Internet | D22: Share of the population that is online | E22: Other (explain) | F22: Quantitative | G22: % of population | H22: Higher is better | I22: World Development Indicators, World Bank | J22: https://databank.worldbank.org/source/world-development-indicators | L22: Not checked | M22: Not checked | N22: Not checked | O22: Not checked | P22: Not checked | Q22: Not checked | R22: =IF(C22="","",COUNTIF(L22:Q22,"Yes")) | V22: =IF(U22="Yes",IF(R22=6,"OK","Coverage gap"),"") | W22: Instructor
A23: =IF(B23="","",UPPER(LEFT(B23,2))&TEXT(COUNTIF(B$2:B23,B23),"00")) | B23: Technological | C23: Logistics Performance Index | D23: Customs, infrastructure, shipments, competence, tracking and timeliness | E23: Import and regulation | F23: Quantitative | G23: Score 1 to 5 | H23: Higher is better | I23: Logistics Performance Index, World Bank | J23: https://lpi.worldbank.org/ | L23: Not checked | M23: Not checked | N23: Not checked | O23: Not checked | P23: Not checked | Q23: Not checked | R23: =IF(C23="","",COUNTIF(L23:Q23,"Yes")) | V23: =IF(U23="Yes",IF(R23=6,"OK","Coverage gap"),"") | W23: Instructor | Z23: The survey-based index ends with the 2023 edition.
A24: =IF(B24="","",UPPER(LEFT(B24,2))&TEXT(COUNTIF(B$2:B24,B24),"00")) | B24: Technological | C24: Global Innovation Index | D24: Innovation capability, seven pillars | E24: Other (explain) | F24: Quantitative | G24: Score 0 to 100 | H24: Higher is better | I24: WIPO | J24: https://www.wipo.int/web/global-innovation-index | L24: Not checked | M24: Not checked | N24: Not checked | O24: Not checked | P24: Not checked | Q24: Not checked | R24: =IF(C24="","",COUNTIF(L24:Q24,"Yes")) | V24: =IF(U24="Yes",IF(R24=6,"OK","Coverage gap"),"") | W24: Instructor
A25: =IF(B25="","",UPPER(LEFT(B25,2))&TEXT(COUNTIF(B$2:B25,B25),"00")) | B25: Technological | C25: Online retail and food delivery share | D25: Share of grocery or coffee sales that is made online | E25: Premium coffee segment | F25: Quantitative | G25: % of sales | H25: Higher is better | I25: Euromonitor Passport (WU library) | J25: https://www.euromonitor.com/our-expertise/passport | L25: Not checked | M25: Not checked | N25: Not checked | O25: Not checked | P25: Not checked | Q25: Not checked | R25: =IF(C25="","",COUNTIF(L25:Q25,"Yes")) | V25: =IF(U25="Yes",IF(R25=6,"OK","Coverage gap"),"") | W25: Instructor | Z25: Check whether your category is available.
A26: =IF(B26="","",UPPER(LEFT(B26,2))&TEXT(COUNTIF(B$2:B26,B26),"00")) | B26: Technological | C26: Account ownership, adults | D26: Share of adults with a bank or mobile money account | E26: Other (explain) | F26: Quantitative | G26: % of adults | H26: Higher is better | I26: Global Findex, World Bank | J26: https://www.worldbank.org/en/publication/globalfindex | L26: Not checked | M26: Not checked | N26: Not checked | O26: Not checked | P26: Not checked | Q26: Not checked | R26: =IF(C26="","",COUNTIF(L26:Q26,"Yes")) | V26: =IF(U26="Yes",IF(R26=6,"OK","Coverage gap"),"") | W26: Instructor | Z26: Not in the instructor's background collection: check coverage and the latest edition.
A27: =IF(B27="","",UPPER(LEFT(B27,2))&TEXT(COUNTIF(B$2:B27,B27),"00")) | B27: Environmental | C27: Climate vulnerability and readiness | D27: Exposure to climate change and readiness to adapt | E27: Other (explain) | F27: Quantitative | G27: Score 0 to 100 | H27: Higher is better | I27: ND-GAIN Country Index | J27: https://gain.nd.edu/our-work/country-index/download-data/ | L27: Not checked | M27: Not checked | N27: Not checked | O27: Not checked | P27: Not checked | Q27: Not checked | R27: =IF(C27="","",COUNTIF(L27:Q27,"Yes")) | V27: =IF(U27="Yes",IF(R27=6,"OK","Coverage gap"),"") | W27: Instructor
A28: =IF(B28="","",UPPER(LEFT(B28,2))&TEXT(COUNTIF(B$2:B28,B28),"00")) | B28: Environmental | C28: Environmental Performance Index | D28: Performance on environmental health and ecosystem vitality | E28: Other (explain) | F28: Quantitative | G28: Score 0 to 100 | H28: Higher is better | I28: Yale Environmental Performance Index | J28: https://epi.yale.edu/ | L28: Not checked | M28: Not checked | N28: Not checked | O28: Not checked | P28: Not checked | Q28: Not checked | R28: =IF(C28="","",COUNTIF(L28:Q28,"Yes")) | V28: =IF(U28="Yes",IF(R28=6,"OK","Coverage gap"),"") | W28: Instructor | Z28: Not in the instructor's background collection: check coverage and the latest edition.
A29: =IF(B29="","",UPPER(LEFT(B29,2))&TEXT(COUNTIF(B$2:B29,B29),"00")) | B29: Environmental | C29: Demand for certified and sustainable coffee | D29: How strongly buyers ask for certified or sustainably sourced coffee | E29: Premium coffee segment | F29: Qualitative rubric | G29: Score 1 to 5 | H29: Higher is better | I29: Industry reports, certification bodies | L29: Not checked | M29: Not checked | N29: Not checked | O29: Not checked | P29: Not checked | Q29: Not checked | R29: =IF(C29="","",COUNTIF(L29:Q29,"Yes")) | V29: =IF(U29="Yes",IF(R29=6,"OK","Coverage gap"),"") | W29: Instructor | Z29: Define the score levels in the comment.
A30: =IF(B30="","",UPPER(LEFT(B30,2))&TEXT(COUNTIF(B$2:B30,B30),"00")) | B30: Environmental | C30: Domestic coffee production | D30: Volume of coffee produced in the country | E30: Competitive landscape | F30: Quantitative | G30: Bags or tonnes (check the unit) | H30: Decide and explain | I30: International Coffee Organization; USDA Foreign Agricultural Service | J30: https://www.ico.org/ | L30: Not checked | M30: Not checked | N30: Not checked | O30: Not checked | P30: Not checked | Q30: Not checked | R30: =IF(C30="","",COUNTIF(L30:Q30,"Yes")) | V30: =IF(U30="Yes",IF(R30=6,"OK","Coverage gap"),"") | W30: Instructor | Z30: Large production can mean strong local roasters and low prices. Decide how you treat it and explain.
A31: =IF(B31="","",UPPER(LEFT(B31,2))&TEXT(COUNTIF(B$2:B31,B31),"00")) | B31: Legal | C31: Regulatory quality | D31: Ability of the government to set and apply sound regulation | E31: Import and regulation | F31: Quantitative | G31: Estimate, about -2.5 to 2.5 | H31: Higher is better | I31: Worldwide Governance Indicators, World Bank | J31: https://www.worldbank.org/en/publication/worldwide-governance-indicators | L31: Not checked | M31: Not checked | N31: Not checked | O31: Not checked | P31: Not checked | Q31: Not checked | R31: =IF(C31="","",COUNTIF(L31:Q31,"Yes")) | V31: =IF(U31="Yes",IF(R31=6,"OK","Coverage gap"),"") | W31: Instructor
A32: =IF(B32="","",UPPER(LEFT(B32,2))&TEXT(COUNTIF(B$2:B32,B32),"00")) | B32: Legal | C32: Rule of law | D32: Confidence in contract enforcement, property rights and the courts | E32: Import and regulation | F32: Quantitative | G32: Estimate, about -2.5 to 2.5 | H32: Higher is better | I32: Worldwide Governance Indicators, World Bank | J32: https://www.worldbank.org/en/publication/worldwide-governance-indicators | L32: Not checked | M32: Not checked | N32: Not checked | O32: Not checked | P32: Not checked | Q32: Not checked | R32: =IF(C32="","",COUNTIF(L32:Q32,"Yes")) | V32: =IF(U32="Yes",IF(R32=6,"OK","Coverage gap"),"") | W32: Instructor | Z32: Matters for contracts with a local partner.
A33: =IF(B33="","",UPPER(LEFT(B33,2))&TEXT(COUNTIF(B$2:B33,B33),"00")) | B33: Legal | C33: Product, labelling and certification requirements for coffee | D33: Rules that apply to roasted coffee imported from the EU | E33: Import and regulation | F33: Qualitative rubric | G33: Score 1 to 5 (5 = few barriers) | H33: Higher is better | I33: EU Access2Markets | J33: https://trade.ec.europa.eu/access-to-markets/en/content/what-access2markets-0 | L33: Not checked | M33: Not checked | N33: Not checked | O33: Not checked | P33: Not checked | Q33: Not checked | R33: =IF(C33="","",COUNTIF(L33:Q33,"Yes")) | V33: =IF(U33="Yes",IF(R33=6,"OK","Coverage gap"),"") | W33: Instructor
A34: =IF(B34="","",UPPER(LEFT(B34,2))&TEXT(COUNTIF(B$2:B34,B34),"00")) | B34: Legal | C34: Trademark protection | D34: Ease and reliability of registering and protecting a brand | E34: Other (explain) | F34: Qualitative rubric | G34: Score 1 to 5 | H34: Higher is better | I34: National trademark offices; WIPO | J34: https://www.wipo.int/ | L34: Not checked | M34: Not checked | N34: Not checked | O34: Not checked | P34: Not checked | Q34: Not checked | R34: =IF(C34="","",COUNTIF(L34:Q34,"Yes")) | V34: =IF(U34="Yes",IF(R34=6,"OK","Coverage gap"),"") | W34: Instructor | Z34: Name the national office you used for each country.
A35: =IF(B35="","",UPPER(LEFT(B35,2))&TEXT(COUNTIF(B$2:B35,B35),"00")) | B35: Legal | C35: Rules for ending a distribution agreement | D35: Legal protection of local distributors and the cost of ending a contract | E35: Other (explain) | F35: Qualitative rubric | G35: Score 1 to 5 | H35: Decide and explain | I35: Law firm guides; national law | L35: Not checked | M35: Not checked | N35: Not checked | O35: Not checked | P35: Not checked | Q35: Not checked | R35: =IF(C35="","",COUNTIF(L35:Q35,"Yes")) | V35: =IF(U35="Yes",IF(R35=6,"OK","Coverage gap"),"") | W35: Instructor | Z35: Relevant for the local partner model. Strong protection can make an exit expensive.
A36: =IF(B36="","",UPPER(LEFT(B36,2))&TEXT(COUNTIF(B$2:B36,B36),"00")) | B36: Legal | C36: Ease of doing business (Business Ready) | D36: Scores on topics such as business entry, trade and taxation | E36: Import and regulation | F36: Quantitative | G36: Score 0 to 100 | H36: Higher is better | I36: Business Ready, World Bank | J36: https://www.worldbank.org/en/businessready/publications-2024 | L36: Not checked | M36: Not checked | N36: Not checked | O36: Not checked | P36: Not checked | Q36: Not checked | R36: =IF(C36="","",COUNTIF(L36:Q36,"Yes")) | V36: =IF(U36="Yes",IF(R36=6,"OK","Coverage gap"),"") | W36: Instructor | Z36: Coverage was limited to 50 economies in 2024: check all six countries.
A37: =IF(B37="","",UPPER(LEFT(B37,2))&TEXT(COUNTIF(B$2:B37,B37),"00")) | R37: =IF(C37="","",COUNTIF(L37:Q37,"Yes")) | V37: =IF(U37="Yes",IF(R37=6,"OK","Coverage gap"),"")
A38: =IF(B38="","",UPPER(LEFT(B38,2))&TEXT(COUNTIF(B$2:B38,B38),"00")) | R38: =IF(C38="","",COUNTIF(L38:Q38,"Yes")) | V38: =IF(U38="Yes",IF(R38=6,"OK","Coverage gap"),"")
A39: =IF(B39="","",UPPER(LEFT(B39,2))&TEXT(COUNTIF(B$2:B39,B39),"00")) | R39: =IF(C39="","",COUNTIF(L39:Q39,"Yes")) | V39: =IF(U39="Yes",IF(R39=6,"OK","Coverage gap"),"")
A40: =IF(B40="","",UPPER(LEFT(B40,2))&TEXT(COUNTIF(B$2:B40,B40),"00")) | R40: =IF(C40="","",COUNTIF(L40:Q40,"Yes")) | V40: =IF(U40="Yes",IF(R40=6,"OK","Coverage gap"),"")
...

Sheet Summary
A1: Summary of your indicator search
A2: All figures on this tab are calculated from the Long list. Only the three blue settings can be changed, and only by the instructor.
A4: Minimum candidate indicators per PESTEL dimension | B4: 3
A5: Shortlist: minimum number of indicators | B5: 8
A6: Shortlist: maximum number of indicators | B6: 14
A8: PESTEL dimension | B8: Candidate indicators | C8: Covering all six countries | D8: Shortlisted | E8: Status
A9: Political | B9: =COUNTIFS('Long list'!$B$2:$B$100,$A9,'Long list'!$C$2:$C$100,"<>") | C9: =COUNTIFS('Long list'!$B$2:$B$100,$A9,'Long list'!$C$2:$C$100,"<>",'Long list'!$R$2:$R$100,6) | D9: =COUNTIFS('Long list'!$B$2:$B$100,$A9,'Long list'!$U$2:$U$100,"Yes") | E9: =IF(B9<$B$4,"Search for more indicators",IF(D9=0,"Shortlist at least one","OK"))
A10: Economic | B10: =COUNTIFS('Long list'!$B$2:$B$100,$A10,'Long list'!$C$2:$C$100,"<>") | C10: =COUNTIFS('Long list'!$B$2:$B$100,$A10,'Long list'!$C$2:$C$100,"<>",'Long list'!$R$2:$R$100,6) | D10: =COUNTIFS('Long list'!$B$2:$B$100,$A10,'Long list'!$U$2:$U$100,"Yes") | E10: =IF(B10<$B$4,"Search for more indicators",IF(D10=0,"Shortlist at least one","OK"))
A11: Social | B11: =COUNTIFS('Long list'!$B$2:$B$100,$A11,'Long list'!$C$2:$C$100,"<>") | C11: =COUNTIFS('Long list'!$B$2:$B$100,$A11,'Long list'!$C$2:$C$100,"<>",'Long list'!$R$2:$R$100,6) | D11: =COUNTIFS('Long list'!$B$2:$B$100,$A11,'Long list'!$U$2:$U$100,"Yes") | E11: =IF(B11<$B$4,"Search for more indicators",IF(D11=0,"Shortlist at least one","OK"))
A12: Technological | B12: =COUNTIFS('Long list'!$B$2:$B$100,$A12,'Long list'!$C$2:$C$100,"<>") | C12: =COUNTIFS('Long list'!$B$2:$B$100,$A12,'Long list'!$C$2:$C$100,"<>",'Long list'!$R$2:$R$100,6) | D12: =COUNTIFS('Long list'!$B$2:$B$100,$A12,'Long list'!$U$2:$U$100,"Yes") | E12: =IF(B12<$B$4,"Search for more indicators",IF(D12=0,"Shortlist at least one","OK"))
A13: Environmental | B13: =COUNTIFS('Long list'!$B$2:$B$100,$A13,'Long list'!$C$2:$C$100,"<>") | C13: =COUNTIFS('Long list'!$B$2:$B$100,$A13,'Long list'!$C$2:$C$100,"<>",'Long list'!$R$2:$R$100,6) | D13: =COUNTIFS('Long list'!$B$2:$B$100,$A13,'Long list'!$U$2:$U$100,"Yes") | E13: =IF(B13<$B$4,"Search for more indicators",IF(D13=0,"Shortlist at least one","OK"))
A14: Legal | B14: =COUNTIFS('Long list'!$B$2:$B$100,$A14,'Long list'!$C$2:$C$100,"<>") | C14: =COUNTIFS('Long list'!$B$2:$B$100,$A14,'Long list'!$C$2:$C$100,"<>",'Long list'!$R$2:$R$100,6) | D14: =COUNTIFS('Long list'!$B$2:$B$100,$A14,'Long list'!$U$2:$U$100,"Yes") | E14: =IF(B14<$B$4,"Search for more indicators",IF(D14=0,"Shortlist at least one","OK"))
A15: Total | B15: =SUM(B9:B14) | C15: =SUM(C9:C14) | D15: =SUM(D9:D14)
A17: Shortlist size | B17: =IF(D15<$B$5,"Too few: shortlist more",IF(D15>$B$6,"Too many: cut down","Within the range"))
A18: Shortlisted indicators without data for all six countries | B18: =COUNTIFS('Long list'!$U$2:$U$100,"Yes",'Long list'!$R$2:$R$100,"<6")
A20: Julius Meinl dimension | B20: Shortlisted indicators | C20: Status
A21: Premium coffee segment | B21: =COUNTIFS('Long list'!$E$2:$E$100,$A21,'Long list'!$U$2:$U$100,"Yes") | C21: =IF($A21="Other (explain)","",IF(B21=0,"No indicator yet","OK"))
A22: Tourism and hotels | B22: =COUNTIFS('Long list'!$E$2:$E$100,$A22,'Long list'!$U$2:$U$100,"Yes") | C22: =IF($A22="Other (explain)","",IF(B22=0,"No indicator yet","OK"))
A23: Purchasing power | B23: =COUNTIFS('Long list'!$E$2:$E$100,$A23,'Long list'!$U$2:$U$100,"Yes") | C23: =IF($A23="Other (explain)","",IF(B23=0,"No indicator yet","OK"))
A24: Competitive landscape | B24: =COUNTIFS('Long list'!$E$2:$E$100,$A24,'Long list'!$U$2:$U$100,"Yes") | C24: =IF($A24="Other (explain)","",IF(B24=0,"No indicator yet","OK"))
A25: Import and regulation | B25: =COUNTIFS('Long list'!$E$2:$E$100,$A25,'Long list'!$U$2:$U$100,"Yes") | C25: =IF($A25="Other (explain)","",IF(B25=0,"No indicator yet","OK"))
A26: Coffee culture | B26: =COUNTIFS('Long list'!$E$2:$E$100,$A26,'Long list'!$U$2:$U$100,"Yes") | C26: =IF($A26="Other (explain)","",IF(B26=0,"No indicator yet","OK"))
A27: Other (explain) | B27: =COUNTIFS('Long list'!$E$2:$E$100,$A27,'Long list'!$U$2:$U$100,"Yes") | C27: =IF($A27="Other (explain)","",IF(B27=0,"No indicator yet","OK"))

Sheet Sources
A1: Data source | B1: Publisher | C1: What you can find | D1: PESTEL dimensions | E1: Access | F1: Link
A2: World Development Indicators | B2: World Bank | C2: About 1,400 indicators for 217 economies: GDP, consumption, population, urbanisation, tourism, internet use. | D2: Economic; Social; Technological | E2: Free | F2: https://databank.worldbank.org/source/world-development-indicators
A3: Worldwide Governance Indicators | B3: World Bank | C3: Six governance dimensions for about 200 economies, with standard errors. | D3: Political; Legal | E3: Free | F3: https://www.worldbank.org/en/publication/worldwide-governance-indicators
A4: World Economic Outlook | B4: IMF | C4: Macro data and projections: growth, inflation, GDP. | D4: Economic | E4: Free | F4: https://data.imf.org/datasets/WEO
A5: Corruption Perceptions Index | B5: Transparency International | C5: Perceived public-sector corruption, 0 to 100. | D5: Political | E5: Free | F5: https://www.transparency.org/en/cpi/2025
A6: Index of Economic Freedom | B6: The Heritage Foundation | C6: Overall score and 12 component scores. | D6: Political; Legal | E6: Free | F6: https://www.heritage.org/index/
A7: Country risk assessments | B7: Coface | C7: Country risk ratings on an eight-level scale for about 160 countries. | D7: Political; Economic | E7: Free | F7: https://www.coface.com/news-economy-and-insights/business-risk-dashboard/country-risk-files
A8: Access2Markets | B8: European Commission, DG Trade | C8: Duties, taxes, product requirements and rules of origin for EU exporters. | D8: Political; Economic; Legal | E8: Free | F8: https://trade.ec.europa.eu/access-to-markets/en/content/what-access2markets-0
A9: Tariff and trade data | B9: World Trade Organization | C9: Applied and bound tariffs by product, trade statistics. | D9: Economic; Legal | E9: Free | F9: https://stats.wto.org/
A10: Trade Map | B10: International Trade Centre | C10: Imports, exports and tariffs by product (HS codes) and country. | D10: Economic | E10: Free (login) | F10: https://www.trademap.org/
A11: UN Comtrade | B11: United Nations | C11: Bilateral trade flows by HS product. | D11: Economic | E11: Free (login) | F11: https://comtradeplus.un.org/
A12: Coffee statistics | B12: International Coffee Organization | C12: Production, consumption and trade of coffee by country. | D12: Social; Environmental; Economic | E12: Free (check what is open) | F12: https://www.ico.org/
... A24: Reports and country profiles | B24: WKO AUSSENWIRTSCHAFT | C24: Country and sector reports from the Austrian trade offices. | D24: Political; Economic; Legal | E24: Free (some need login) | F24: https://www.wko.at/aussenwirtschaft/berichte
A26: Access labels follow the instructor's background collection. Entries marked "not checked" were added from general knowledge: verify them.
